2017-05-09 00:57:42,175 198.14.218.72.90 tries to log in but has not registered yet
2017-05-09 00:57:47,556 132.70.170.234.130 has logged in
2017-05-09 00:57:47,710 file_cache is unavailable when using oauth2client >= 4.0.0
Traceback (most recent call last):
  File "/usr/local/lib/python3.6/site-packages/google_api_python_client-1.6.2-py3.6.egg/googleapiclient/discovery_cache/__init__.py", line 36, in autodetect
    from google.appengine.api import memcache
ModuleNotFoundError: No module named 'google'

During handling of the above exception, another exception occurred:

Traceback (most recent call last):
  File "/usr/local/lib/python3.6/site-packages/google_api_python_client-1.6.2-py3.6.egg/googleapiclient/discovery_cache/file_cache.py", line 33, in <module>
    from oauth2client.contrib.locked_file import LockedFile
ModuleNotFoundError: No module named 'oauth2client.contrib.locked_file'

During handling of the above exception, another exception occurred:

Traceback (most recent call last):
  File "/usr/local/lib/python3.6/site-packages/google_api_python_client-1.6.2-py3.6.egg/googleapiclient/discovery_cache/file_cache.py", line 37, in <module>
    from oauth2client.locked_file import LockedFile
ModuleNotFoundError: No module named 'oauth2client.locked_file'

During handling of the above exception, another exception occurred:

Traceback (most recent call last):
  File "/usr/local/lib/python3.6/site-packages/google_api_python_client-1.6.2-py3.6.egg/googleapiclient/discovery_cache/__init__.py", line 41, in autodetect
    from . import file_cache
  File "/usr/local/lib/python3.6/site-packages/google_api_python_client-1.6.2-py3.6.egg/googleapiclient/discovery_cache/file_cache.py", line 41, in <module>
    'file_cache is unavailable when using oauth2client >= 4.0.0')
ImportError: file_cache is unavailable when using oauth2client >= 4.0.0
2017-05-09 00:57:47,743 URL being requested: GET https://www.googleapis.com/discovery/v1/apis/calendar/v3/rest
2017-05-09 00:57:48,209 URL being requested: GET https://www.googleapis.com/calendar/v3/calendars/primary/events?timeMin=2017-05-09T04%3A57%3A48.153594Z&maxResults=10&singleEvents=true&orderBy=startTime&alt=json
2017-05-09 00:57:48,606 132.70.170.234.130's event has been collected
2017-05-09 00:59:59,702 132.70.170.234.130 has logged in
2017-05-09 00:59:59,852 file_cache is unavailable when using oauth2client >= 4.0.0
Traceback (most recent call last):
  File "/usr/local/lib/python3.6/site-packages/google_api_python_client-1.6.2-py3.6.egg/googleapiclient/discovery_cache/__init__.py", line 36, in autodetect
    from google.appengine.api import memcache
ModuleNotFoundError: No module named 'google'

During handling of the above exception, another exception occurred:

Traceback (most recent call last):
  File "/usr/local/lib/python3.6/site-packages/google_api_python_client-1.6.2-py3.6.egg/googleapiclient/discovery_cache/file_cache.py", line 33, in <module>
    from oauth2client.contrib.locked_file import LockedFile
ModuleNotFoundError: No module named 'oauth2client.contrib.locked_file'

During handling of the above exception, another exception occurred:

Traceback (most recent call last):
  File "/usr/local/lib/python3.6/site-packages/google_api_python_client-1.6.2-py3.6.egg/googleapiclient/discovery_cache/file_cache.py", line 37, in <module>
    from oauth2client.locked_file import LockedFile
ModuleNotFoundError: No module named 'oauth2client.locked_file'

During handling of the above exception, another exception occurred:

Traceback (most recent call last):
  File "/usr/local/lib/python3.6/site-packages/google_api_python_client-1.6.2-py3.6.egg/googleapiclient/discovery_cache/__init__.py", line 41, in autodetect
    from . import file_cache
  File "/usr/local/lib/python3.6/site-packages/google_api_python_client-1.6.2-py3.6.egg/googleapiclient/discovery_cache/file_cache.py", line 41, in <module>
    'file_cache is unavailable when using oauth2client >= 4.0.0')
ImportError: file_cache is unavailable when using oauth2client >= 4.0.0
2017-05-09 00:59:59,886 URL being requested: GET https://www.googleapis.com/discovery/v1/apis/calendar/v3/rest
2017-05-09 01:00:00,343 URL being requested: GET https://www.googleapis.com/calendar/v3/calendars/primary/events?timeMin=2017-05-09T05%3A00%3A00.283558Z&maxResults=10&singleEvents=true&orderBy=startTime&alt=json
2017-05-09 01:00:00,462 132.70.170.234.130's event has been collected
2017-05-09 01:00:01,538 Notify 132.70.170.234.130 event in 5 min
