2017-05-07 21:10:24,519 211.127.98.139.69 has logged in
2017-05-07 21:13:52,037 211.127.98.139.69 has logged in
2017-05-07 21:25:30,836 211.127.98.139.69 has logged in
2017-05-07 21:26:47,418 211.127.98.139.69 has logged in
2017-05-07 21:27:45,565 211.127.98.139.69 has logged in
2017-05-07 21:28:29,215 211.127.98.139.69 has logged in
2017-05-07 21:29:25,825 211.127.98.139.69 has logged in
2017-05-07 21:29:25,853 file_cache is unavailable when using oauth2client >= 4.0.0
Traceback (most recent call last):
  File "/usr/local/lib/python3.6/site-packages/google_api_python_client-1.6.2-py3.6.egg/googleapiclient/discovery_cache/__init__.py", line 36, in autodetect
    from google.appengine.api import memcache
ModuleNotFoundError: No module named 'google'

During handling of the above exception, another exception occurred:

Traceback (most recent call last):
  File "/usr/local/lib/python3.6/site-packages/google_api_python_client-1.6.2-py3.6.egg/googleapiclient/discovery_cache/file_cache.py", line 33, in <module>
    from oauth2client.contrib.locked_file import LockedFile
ModuleNotFoundError: No module named 'oauth2client.contrib.locked_file'

During handling of the above exception, another exception occurred:

Traceback (most recent call last):
  File "/usr/local/lib/python3.6/site-packages/google_api_python_client-1.6.2-py3.6.egg/googleapiclient/discovery_cache/file_cache.py", line 37, in <module>
    from oauth2client.locked_file import LockedFile
ModuleNotFoundError: No module named 'oauth2client.locked_file'

During handling of the above exception, another exception occurred:

Traceback (most recent call last):
  File "/usr/local/lib/python3.6/site-packages/google_api_python_client-1.6.2-py3.6.egg/googleapiclient/discovery_cache/__init__.py", line 41, in autodetect
    from . import file_cache
  File "/usr/local/lib/python3.6/site-packages/google_api_python_client-1.6.2-py3.6.egg/googleapiclient/discovery_cache/file_cache.py", line 41, in <module>
    'file_cache is unavailable when using oauth2client >= 4.0.0')
ImportError: file_cache is unavailable when using oauth2client >= 4.0.0
2017-05-07 21:29:25,856 URL being requested: GET https://www.googleapis.com/discovery/v1/apis/calendar/v3/rest
2017-05-07 21:29:26,081 URL being requested: GET https://www.googleapis.com/calendar/v3/calendars/primary/events?timeMin=2017-05-07T21%3A29%3A26.050841Z&maxResults=10&singleEvents=true&orderBy=startTime&alt=json
2017-05-07 21:29:26,127 Refreshing due to a 401 (attempt 1/2)
2017-05-07 21:29:26,128 Refreshing access_token
2017-05-07 21:29:26,418 211.127.98.139.69's event has been collected
2017-05-07 21:30:04,968 211.127.98.139.69 has logged in
2017-05-07 21:30:04,988 file_cache is unavailable when using oauth2client >= 4.0.0
Traceback (most recent call last):
  File "/usr/local/lib/python3.6/site-packages/google_api_python_client-1.6.2-py3.6.egg/googleapiclient/discovery_cache/__init__.py", line 36, in autodetect
    from google.appengine.api import memcache
ModuleNotFoundError: No module named 'google'

During handling of the above exception, another exception occurred:

Traceback (most recent call last):
  File "/usr/local/lib/python3.6/site-packages/google_api_python_client-1.6.2-py3.6.egg/googleapiclient/discovery_cache/file_cache.py", line 33, in <module>
    from oauth2client.contrib.locked_file import LockedFile
ModuleNotFoundError: No module named 'oauth2client.contrib.locked_file'

During handling of the above exception, another exception occurred:

Traceback (most recent call last):
  File "/usr/local/lib/python3.6/site-packages/google_api_python_client-1.6.2-py3.6.egg/googleapiclient/discovery_cache/file_cache.py", line 37, in <module>
    from oauth2client.locked_file import LockedFile
ModuleNotFoundError: No module named 'oauth2client.locked_file'

During handling of the above exception, another exception occurred:

Traceback (most recent call last):
  File "/usr/local/lib/python3.6/site-packages/google_api_python_client-1.6.2-py3.6.egg/googleapiclient/discovery_cache/__init__.py", line 41, in autodetect
    from . import file_cache
  File "/usr/local/lib/python3.6/site-packages/google_api_python_client-1.6.2-py3.6.egg/googleapiclient/discovery_cache/file_cache.py", line 41, in <module>
    'file_cache is unavailable when using oauth2client >= 4.0.0')
ImportError: file_cache is unavailable when using oauth2client >= 4.0.0
2017-05-07 21:30:05,004 URL being requested: GET https://www.googleapis.com/discovery/v1/apis/calendar/v3/rest
2017-05-07 21:37:18,637 211.127.98.139.69 has logged in
2017-05-07 21:37:18,657 file_cache is unavailable when using oauth2client >= 4.0.0
Traceback (most recent call last):
  File "/usr/local/lib/python3.6/site-packages/google_api_python_client-1.6.2-py3.6.egg/googleapiclient/discovery_cache/__init__.py", line 36, in autodetect
    from google.appengine.api import memcache
ModuleNotFoundError: No module named 'google'

During handling of the above exception, another exception occurred:

Traceback (most recent call last):
  File "/usr/local/lib/python3.6/site-packages/google_api_python_client-1.6.2-py3.6.egg/googleapiclient/discovery_cache/file_cache.py", line 33, in <module>
    from oauth2client.contrib.locked_file import LockedFile
ModuleNotFoundError: No module named 'oauth2client.contrib.locked_file'

During handling of the above exception, another exception occurred:

Traceback (most recent call last):
  File "/usr/local/lib/python3.6/site-packages/google_api_python_client-1.6.2-py3.6.egg/googleapiclient/discovery_cache/file_cache.py", line 37, in <module>
    from oauth2client.locked_file import LockedFile
ModuleNotFoundError: No module named 'oauth2client.locked_file'

During handling of the above exception, another exception occurred:

Traceback (most recent call last):
  File "/usr/local/lib/python3.6/site-packages/google_api_python_client-1.6.2-py3.6.egg/googleapiclient/discovery_cache/__init__.py", line 41, in autodetect
    from . import file_cache
  File "/usr/local/lib/python3.6/site-packages/google_api_python_client-1.6.2-py3.6.egg/googleapiclient/discovery_cache/file_cache.py", line 41, in <module>
    'file_cache is unavailable when using oauth2client >= 4.0.0')
ImportError: file_cache is unavailable when using oauth2client >= 4.0.0
2017-05-07 21:37:18,659 URL being requested: GET https://www.googleapis.com/discovery/v1/apis/calendar/v3/rest
2017-05-07 21:37:18,813 URL being requested: GET https://www.googleapis.com/calendar/v3/calendars/primary/events?timeMin=2017-05-07T21%3A37%3A18.782402Z&maxResults=10&singleEvents=true&orderBy=startTime&alt=json
2017-05-07 21:37:18,860 Refreshing due to a 401 (attempt 1/2)
2017-05-07 21:37:18,861 Refreshing access_token
2017-05-07 21:37:19,138 211.127.98.139.69's event has been collected
2017-05-07 21:55:11,523 211.127.98.139.69 has logged in
2017-05-07 21:55:11,545 file_cache is unavailable when using oauth2client >= 4.0.0
Traceback (most recent call last):
  File "/usr/local/lib/python3.6/site-packages/google_api_python_client-1.6.2-py3.6.egg/googleapiclient/discovery_cache/__init__.py", line 36, in autodetect
    from google.appengine.api import memcache
ModuleNotFoundError: No module named 'google'

During handling of the above exception, another exception occurred:

Traceback (most recent call last):
  File "/usr/local/lib/python3.6/site-packages/google_api_python_client-1.6.2-py3.6.egg/googleapiclient/discovery_cache/file_cache.py", line 33, in <module>
    from oauth2client.contrib.locked_file import LockedFile
ModuleNotFoundError: No module named 'oauth2client.contrib.locked_file'

During handling of the above exception, another exception occurred:

Traceback (most recent call last):
  File "/usr/local/lib/python3.6/site-packages/google_api_python_client-1.6.2-py3.6.egg/googleapiclient/discovery_cache/file_cache.py", line 37, in <module>
    from oauth2client.locked_file import LockedFile
ModuleNotFoundError: No module named 'oauth2client.locked_file'

During handling of the above exception, another exception occurred:

Traceback (most recent call last):
  File "/usr/local/lib/python3.6/site-packages/google_api_python_client-1.6.2-py3.6.egg/googleapiclient/discovery_cache/__init__.py", line 41, in autodetect
    from . import file_cache
  File "/usr/local/lib/python3.6/site-packages/google_api_python_client-1.6.2-py3.6.egg/googleapiclient/discovery_cache/file_cache.py", line 41, in <module>
    'file_cache is unavailable when using oauth2client >= 4.0.0')
ImportError: file_cache is unavailable when using oauth2client >= 4.0.0
2017-05-07 21:55:11,548 URL being requested: GET https://www.googleapis.com/discovery/v1/apis/calendar/v3/rest
2017-05-07 21:55:11,728 URL being requested: GET https://www.googleapis.com/calendar/v3/calendars/primary/events?timeMin=2017-05-07T21%3A55%3A11.698919Z&maxResults=10&singleEvents=true&orderBy=startTime&alt=json
2017-05-07 21:55:11,789 Refreshing due to a 401 (attempt 1/2)
2017-05-07 21:55:11,790 Refreshing access_token
2017-05-07 21:55:12,193 211.127.98.139.69's event has been collected
2017-05-07 21:56:10,712 211.127.98.139.69 has logged in
2017-05-07 21:56:10,734 file_cache is unavailable when using oauth2client >= 4.0.0
Traceback (most recent call last):
  File "/usr/local/lib/python3.6/site-packages/google_api_python_client-1.6.2-py3.6.egg/googleapiclient/discovery_cache/__init__.py", line 36, in autodetect
    from google.appengine.api import memcache
ModuleNotFoundError: No module named 'google'

During handling of the above exception, another exception occurred:

Traceback (most recent call last):
  File "/usr/local/lib/python3.6/site-packages/google_api_python_client-1.6.2-py3.6.egg/googleapiclient/discovery_cache/file_cache.py", line 33, in <module>
    from oauth2client.contrib.locked_file import LockedFile
ModuleNotFoundError: No module named 'oauth2client.contrib.locked_file'

During handling of the above exception, another exception occurred:

Traceback (most recent call last):
  File "/usr/local/lib/python3.6/site-packages/google_api_python_client-1.6.2-py3.6.egg/googleapiclient/discovery_cache/file_cache.py", line 37, in <module>
    from oauth2client.locked_file import LockedFile
ModuleNotFoundError: No module named 'oauth2client.locked_file'

During handling of the above exception, another exception occurred:

Traceback (most recent call last):
  File "/usr/local/lib/python3.6/site-packages/google_api_python_client-1.6.2-py3.6.egg/googleapiclient/discovery_cache/__init__.py", line 41, in autodetect
    from . import file_cache
  File "/usr/local/lib/python3.6/site-packages/google_api_python_client-1.6.2-py3.6.egg/googleapiclient/discovery_cache/file_cache.py", line 41, in <module>
    'file_cache is unavailable when using oauth2client >= 4.0.0')
ImportError: file_cache is unavailable when using oauth2client >= 4.0.0
2017-05-07 21:56:10,737 URL being requested: GET https://www.googleapis.com/discovery/v1/apis/calendar/v3/rest
2017-05-07 21:56:10,903 URL being requested: GET https://www.googleapis.com/calendar/v3/calendars/primary/events?timeMin=2017-05-07T21%3A56%3A10.873203Z&maxResults=10&singleEvents=true&orderBy=startTime&alt=json
2017-05-07 21:56:10,948 Refreshing due to a 401 (attempt 1/2)
2017-05-07 21:56:10,949 Refreshing access_token
2017-05-07 21:56:11,256 211.127.98.139.69's event has been collected
2017-05-07 21:57:10,813 211.127.98.139.69 has logged in
2017-05-07 21:57:10,833 file_cache is unavailable when using oauth2client >= 4.0.0
Traceback (most recent call last):
  File "/usr/local/lib/python3.6/site-packages/google_api_python_client-1.6.2-py3.6.egg/googleapiclient/discovery_cache/__init__.py", line 36, in autodetect
    from google.appengine.api import memcache
ModuleNotFoundError: No module named 'google'

During handling of the above exception, another exception occurred:

Traceback (most recent call last):
  File "/usr/local/lib/python3.6/site-packages/google_api_python_client-1.6.2-py3.6.egg/googleapiclient/discovery_cache/file_cache.py", line 33, in <module>
    from oauth2client.contrib.locked_file import LockedFile
ModuleNotFoundError: No module named 'oauth2client.contrib.locked_file'

During handling of the above exception, another exception occurred:

Traceback (most recent call last):
  File "/usr/local/lib/python3.6/site-packages/google_api_python_client-1.6.2-py3.6.egg/googleapiclient/discovery_cache/file_cache.py", line 37, in <module>
    from oauth2client.locked_file import LockedFile
ModuleNotFoundError: No module named 'oauth2client.locked_file'

During handling of the above exception, another exception occurred:

Traceback (most recent call last):
  File "/usr/local/lib/python3.6/site-packages/google_api_python_client-1.6.2-py3.6.egg/googleapiclient/discovery_cache/__init__.py", line 41, in autodetect
    from . import file_cache
  File "/usr/local/lib/python3.6/site-packages/google_api_python_client-1.6.2-py3.6.egg/googleapiclient/discovery_cache/file_cache.py", line 41, in <module>
    'file_cache is unavailable when using oauth2client >= 4.0.0')
ImportError: file_cache is unavailable when using oauth2client >= 4.0.0
2017-05-07 21:57:10,835 URL being requested: GET https://www.googleapis.com/discovery/v1/apis/calendar/v3/rest
2017-05-07 21:57:10,993 URL being requested: GET https://www.googleapis.com/calendar/v3/calendars/primary/events?timeMin=2017-05-07T21%3A57%3A10.964093Z&maxResults=10&singleEvents=true&orderBy=startTime&alt=json
2017-05-07 21:57:11,061 Refreshing due to a 401 (attempt 1/2)
2017-05-07 21:57:11,062 Refreshing access_token
2017-05-07 21:57:11,344 211.127.98.139.69's event has been collected
2017-05-07 21:57:24,637 211.127.98.139.69 has logged in
2017-05-07 21:57:24,656 file_cache is unavailable when using oauth2client >= 4.0.0
Traceback (most recent call last):
  File "/usr/local/lib/python3.6/site-packages/google_api_python_client-1.6.2-py3.6.egg/googleapiclient/discovery_cache/__init__.py", line 36, in autodetect
    from google.appengine.api import memcache
ModuleNotFoundError: No module named 'google'

During handling of the above exception, another exception occurred:

Traceback (most recent call last):
  File "/usr/local/lib/python3.6/site-packages/google_api_python_client-1.6.2-py3.6.egg/googleapiclient/discovery_cache/file_cache.py", line 33, in <module>
    from oauth2client.contrib.locked_file import LockedFile
ModuleNotFoundError: No module named 'oauth2client.contrib.locked_file'

During handling of the above exception, another exception occurred:

Traceback (most recent call last):
  File "/usr/local/lib/python3.6/site-packages/google_api_python_client-1.6.2-py3.6.egg/googleapiclient/discovery_cache/file_cache.py", line 37, in <module>
    from oauth2client.locked_file import LockedFile
ModuleNotFoundError: No module named 'oauth2client.locked_file'

During handling of the above exception, another exception occurred:

Traceback (most recent call last):
  File "/usr/local/lib/python3.6/site-packages/google_api_python_client-1.6.2-py3.6.egg/googleapiclient/discovery_cache/__init__.py", line 41, in autodetect
    from . import file_cache
  File "/usr/local/lib/python3.6/site-packages/google_api_python_client-1.6.2-py3.6.egg/googleapiclient/discovery_cache/file_cache.py", line 41, in <module>
    'file_cache is unavailable when using oauth2client >= 4.0.0')
ImportError: file_cache is unavailable when using oauth2client >= 4.0.0
2017-05-07 21:57:24,659 URL being requested: GET https://www.googleapis.com/discovery/v1/apis/calendar/v3/rest
2017-05-07 21:57:24,821 URL being requested: GET https://www.googleapis.com/calendar/v3/calendars/primary/events?timeMin=2017-05-07T21%3A57%3A24.791593Z&maxResults=10&singleEvents=true&orderBy=startTime&alt=json
2017-05-07 21:57:24,857 Refreshing due to a 401 (attempt 1/2)
2017-05-07 21:57:24,857 Refreshing access_token
2017-05-07 21:57:25,107 211.127.98.139.69's event has been collected
2017-05-07 22:00:24,984 211.127.98.139.69 has logged in
2017-05-07 22:00:25,005 file_cache is unavailable when using oauth2client >= 4.0.0
Traceback (most recent call last):
  File "/usr/local/lib/python3.6/site-packages/google_api_python_client-1.6.2-py3.6.egg/googleapiclient/discovery_cache/__init__.py", line 36, in autodetect
    from google.appengine.api import memcache
ModuleNotFoundError: No module named 'google'

During handling of the above exception, another exception occurred:

Traceback (most recent call last):
  File "/usr/local/lib/python3.6/site-packages/google_api_python_client-1.6.2-py3.6.egg/googleapiclient/discovery_cache/file_cache.py", line 33, in <module>
    from oauth2client.contrib.locked_file import LockedFile
ModuleNotFoundError: No module named 'oauth2client.contrib.locked_file'

During handling of the above exception, another exception occurred:

Traceback (most recent call last):
  File "/usr/local/lib/python3.6/site-packages/google_api_python_client-1.6.2-py3.6.egg/googleapiclient/discovery_cache/file_cache.py", line 37, in <module>
    from oauth2client.locked_file import LockedFile
ModuleNotFoundError: No module named 'oauth2client.locked_file'

During handling of the above exception, another exception occurred:

Traceback (most recent call last):
  File "/usr/local/lib/python3.6/site-packages/google_api_python_client-1.6.2-py3.6.egg/googleapiclient/discovery_cache/__init__.py", line 41, in autodetect
    from . import file_cache
  File "/usr/local/lib/python3.6/site-packages/google_api_python_client-1.6.2-py3.6.egg/googleapiclient/discovery_cache/file_cache.py", line 41, in <module>
    'file_cache is unavailable when using oauth2client >= 4.0.0')
ImportError: file_cache is unavailable when using oauth2client >= 4.0.0
2017-05-07 22:00:25,008 URL being requested: GET https://www.googleapis.com/discovery/v1/apis/calendar/v3/rest
2017-05-07 22:00:25,170 URL being requested: GET https://www.googleapis.com/calendar/v3/calendars/primary/events?timeMin=2017-05-07T22%3A00%3A25.139236Z&maxResults=10&singleEvents=true&orderBy=startTime&alt=json
2017-05-07 22:00:25,225 Refreshing due to a 401 (attempt 1/2)
2017-05-07 22:00:25,226 Refreshing access_token
2017-05-07 22:00:25,568 211.127.98.139.69's event has been collected
2017-05-07 22:00:25,585 Notify 211.127.98.139.69 event in -30 min
2017-05-07 22:01:51,745 211.127.98.139.69 has logged in
2017-05-07 22:01:51,765 file_cache is unavailable when using oauth2client >= 4.0.0
Traceback (most recent call last):
  File "/usr/local/lib/python3.6/site-packages/google_api_python_client-1.6.2-py3.6.egg/googleapiclient/discovery_cache/__init__.py", line 36, in autodetect
    from google.appengine.api import memcache
ModuleNotFoundError: No module named 'google'

During handling of the above exception, another exception occurred:

Traceback (most recent call last):
  File "/usr/local/lib/python3.6/site-packages/google_api_python_client-1.6.2-py3.6.egg/googleapiclient/discovery_cache/file_cache.py", line 33, in <module>
    from oauth2client.contrib.locked_file import LockedFile
ModuleNotFoundError: No module named 'oauth2client.contrib.locked_file'

During handling of the above exception, another exception occurred:

Traceback (most recent call last):
  File "/usr/local/lib/python3.6/site-packages/google_api_python_client-1.6.2-py3.6.egg/googleapiclient/discovery_cache/file_cache.py", line 37, in <module>
    from oauth2client.locked_file import LockedFile
ModuleNotFoundError: No module named 'oauth2client.locked_file'

During handling of the above exception, another exception occurred:

Traceback (most recent call last):
  File "/usr/local/lib/python3.6/site-packages/google_api_python_client-1.6.2-py3.6.egg/googleapiclient/discovery_cache/__init__.py", line 41, in autodetect
    from . import file_cache
  File "/usr/local/lib/python3.6/site-packages/google_api_python_client-1.6.2-py3.6.egg/googleapiclient/discovery_cache/file_cache.py", line 41, in <module>
    'file_cache is unavailable when using oauth2client >= 4.0.0')
ImportError: file_cache is unavailable when using oauth2client >= 4.0.0
2017-05-07 22:01:51,768 URL being requested: GET https://www.googleapis.com/discovery/v1/apis/calendar/v3/rest
2017-05-07 22:01:51,933 URL being requested: GET https://www.googleapis.com/calendar/v3/calendars/primary/events?timeMin=2017-05-07T22%3A01%3A51.902502Z&maxResults=10&singleEvents=true&orderBy=startTime&alt=json
2017-05-07 22:01:51,969 Refreshing due to a 401 (attempt 1/2)
2017-05-07 22:01:51,970 Refreshing access_token
2017-05-07 22:01:52,253 211.127.98.139.69's event has been collected
2017-05-07 22:01:52,270 Notify 211.127.98.139.69 event in -29 min
2017-05-07 22:03:26,633 211.127.98.139.69 has logged in
2017-05-07 22:03:26,652 file_cache is unavailable when using oauth2client >= 4.0.0
Traceback (most recent call last):
  File "/usr/local/lib/python3.6/site-packages/google_api_python_client-1.6.2-py3.6.egg/googleapiclient/discovery_cache/__init__.py", line 36, in autodetect
    from google.appengine.api import memcache
ModuleNotFoundError: No module named 'google'

During handling of the above exception, another exception occurred:

Traceback (most recent call last):
  File "/usr/local/lib/python3.6/site-packages/google_api_python_client-1.6.2-py3.6.egg/googleapiclient/discovery_cache/file_cache.py", line 33, in <module>
    from oauth2client.contrib.locked_file import LockedFile
ModuleNotFoundError: No module named 'oauth2client.contrib.locked_file'

During handling of the above exception, another exception occurred:

Traceback (most recent call last):
  File "/usr/local/lib/python3.6/site-packages/google_api_python_client-1.6.2-py3.6.egg/googleapiclient/discovery_cache/file_cache.py", line 37, in <module>
    from oauth2client.locked_file import LockedFile
ModuleNotFoundError: No module named 'oauth2client.locked_file'

During handling of the above exception, another exception occurred:

Traceback (most recent call last):
  File "/usr/local/lib/python3.6/site-packages/google_api_python_client-1.6.2-py3.6.egg/googleapiclient/discovery_cache/__init__.py", line 41, in autodetect
    from . import file_cache
  File "/usr/local/lib/python3.6/site-packages/google_api_python_client-1.6.2-py3.6.egg/googleapiclient/discovery_cache/file_cache.py", line 41, in <module>
    'file_cache is unavailable when using oauth2client >= 4.0.0')
ImportError: file_cache is unavailable when using oauth2client >= 4.0.0
2017-05-07 22:03:26,654 URL being requested: GET https://www.googleapis.com/discovery/v1/apis/calendar/v3/rest
2017-05-07 22:03:26,811 URL being requested: GET https://www.googleapis.com/calendar/v3/calendars/primary/events?timeMin=2017-05-07T22%3A03%3A26.782380Z&maxResults=10&singleEvents=true&orderBy=startTime&alt=json
2017-05-07 22:03:26,872 Refreshing due to a 401 (attempt 1/2)
2017-05-07 22:03:26,873 Refreshing access_token
2017-05-07 22:03:27,132 211.127.98.139.69's event has been collected
2017-05-07 22:03:27,149 Notify 211.127.98.139.69 event in -27 min
2017-05-07 22:04:31,888 211.127.98.139.69 has logged in
2017-05-07 22:04:31,907 file_cache is unavailable when using oauth2client >= 4.0.0
Traceback (most recent call last):
  File "/usr/local/lib/python3.6/site-packages/google_api_python_client-1.6.2-py3.6.egg/googleapiclient/discovery_cache/__init__.py", line 36, in autodetect
    from google.appengine.api import memcache
ModuleNotFoundError: No module named 'google'

During handling of the above exception, another exception occurred:

Traceback (most recent call last):
  File "/usr/local/lib/python3.6/site-packages/google_api_python_client-1.6.2-py3.6.egg/googleapiclient/discovery_cache/file_cache.py", line 33, in <module>
    from oauth2client.contrib.locked_file import LockedFile
ModuleNotFoundError: No module named 'oauth2client.contrib.locked_file'

During handling of the above exception, another exception occurred:

Traceback (most recent call last):
  File "/usr/local/lib/python3.6/site-packages/google_api_python_client-1.6.2-py3.6.egg/googleapiclient/discovery_cache/file_cache.py", line 37, in <module>
    from oauth2client.locked_file import LockedFile
ModuleNotFoundError: No module named 'oauth2client.locked_file'

During handling of the above exception, another exception occurred:

Traceback (most recent call last):
  File "/usr/local/lib/python3.6/site-packages/google_api_python_client-1.6.2-py3.6.egg/googleapiclient/discovery_cache/__init__.py", line 41, in autodetect
    from . import file_cache
  File "/usr/local/lib/python3.6/site-packages/google_api_python_client-1.6.2-py3.6.egg/googleapiclient/discovery_cache/file_cache.py", line 41, in <module>
    'file_cache is unavailable when using oauth2client >= 4.0.0')
ImportError: file_cache is unavailable when using oauth2client >= 4.0.0
2017-05-07 22:04:31,910 URL being requested: GET https://www.googleapis.com/discovery/v1/apis/calendar/v3/rest
2017-05-07 22:04:32,073 URL being requested: GET https://www.googleapis.com/calendar/v3/calendars/primary/events?timeMin=2017-05-07T22%3A04%3A32.043274Z&maxResults=10&singleEvents=true&orderBy=startTime&alt=json
2017-05-07 22:04:32,110 Refreshing due to a 401 (attempt 1/2)
2017-05-07 22:04:32,111 Refreshing access_token
2017-05-07 22:04:32,415 211.127.98.139.69's event has been collected
2017-05-07 22:04:32,431 Notify 211.127.98.139.69 event in -26 min
2017-05-07 22:05:39,116 211.127.98.139.69 has logged in
2017-05-07 22:05:39,137 file_cache is unavailable when using oauth2client >= 4.0.0
Traceback (most recent call last):
  File "/usr/local/lib/python3.6/site-packages/google_api_python_client-1.6.2-py3.6.egg/googleapiclient/discovery_cache/__init__.py", line 36, in autodetect
    from google.appengine.api import memcache
ModuleNotFoundError: No module named 'google'

During handling of the above exception, another exception occurred:

Traceback (most recent call last):
  File "/usr/local/lib/python3.6/site-packages/google_api_python_client-1.6.2-py3.6.egg/googleapiclient/discovery_cache/file_cache.py", line 33, in <module>
    from oauth2client.contrib.locked_file import LockedFile
ModuleNotFoundError: No module named 'oauth2client.contrib.locked_file'

During handling of the above exception, another exception occurred:

Traceback (most recent call last):
  File "/usr/local/lib/python3.6/site-packages/google_api_python_client-1.6.2-py3.6.egg/googleapiclient/discovery_cache/file_cache.py", line 37, in <module>
    from oauth2client.locked_file import LockedFile
ModuleNotFoundError: No module named 'oauth2client.locked_file'

During handling of the above exception, another exception occurred:

Traceback (most recent call last):
  File "/usr/local/lib/python3.6/site-packages/google_api_python_client-1.6.2-py3.6.egg/googleapiclient/discovery_cache/__init__.py", line 41, in autodetect
    from . import file_cache
  File "/usr/local/lib/python3.6/site-packages/google_api_python_client-1.6.2-py3.6.egg/googleapiclient/discovery_cache/file_cache.py", line 41, in <module>
    'file_cache is unavailable when using oauth2client >= 4.0.0')
ImportError: file_cache is unavailable when using oauth2client >= 4.0.0
2017-05-07 22:05:39,139 URL being requested: GET https://www.googleapis.com/discovery/v1/apis/calendar/v3/rest
2017-05-07 22:05:39,289 URL being requested: GET https://www.googleapis.com/calendar/v3/calendars/primary/events?timeMin=2017-05-07T22%3A05%3A39.259278Z&maxResults=10&singleEvents=true&orderBy=startTime&alt=json
2017-05-07 22:05:39,356 Refreshing due to a 401 (attempt 1/2)
2017-05-07 22:05:39,357 Refreshing access_token
2017-05-07 22:05:39,837 211.127.98.139.69's event has been collected
2017-05-07 22:05:39,854 Notify 211.127.98.139.69 event in -25 min
2017-05-07 18:40:25,828 Retransmission, Message ID: 15485.
2017-05-07 19:15:38,488 0.152.255.115.20 has logged in
2017-05-07 19:15:38,511 file_cache is unavailable when using oauth2client >= 4.0.0
Traceback (most recent call last):
  File "/usr/local/lib/python3.6/site-packages/googleapiclient/discovery_cache/__init__.py", line 36, in autodetect
    from google.appengine.api import memcache
ModuleNotFoundError: No module named 'google'

During handling of the above exception, another exception occurred:

Traceback (most recent call last):
  File "/usr/local/lib/python3.6/site-packages/googleapiclient/discovery_cache/file_cache.py", line 33, in <module>
    from oauth2client.contrib.locked_file import LockedFile
ModuleNotFoundError: No module named 'oauth2client.contrib.locked_file'

During handling of the above exception, another exception occurred:

Traceback (most recent call last):
  File "/usr/local/lib/python3.6/site-packages/googleapiclient/discovery_cache/file_cache.py", line 37, in <module>
    from oauth2client.locked_file import LockedFile
ModuleNotFoundError: No module named 'oauth2client.locked_file'

During handling of the above exception, another exception occurred:

Traceback (most recent call last):
  File "/usr/local/lib/python3.6/site-packages/googleapiclient/discovery_cache/__init__.py", line 41, in autodetect
    from . import file_cache
  File "/usr/local/lib/python3.6/site-packages/googleapiclient/discovery_cache/file_cache.py", line 41, in <module>
    'file_cache is unavailable when using oauth2client >= 4.0.0')
ImportError: file_cache is unavailable when using oauth2client >= 4.0.0
2017-05-07 19:15:38,515 URL being requested: GET https://www.googleapis.com/discovery/v1/apis/calendar/v3/rest
2017-05-07 19:15:38,673 URL being requested: GET https://www.googleapis.com/calendar/v3/calendars/primary/events?timeMin=2017-05-07T23%3A15%3A38.640549Z&maxResults=10&singleEvents=true&orderBy=startTime&alt=json
2017-05-07 19:15:38,912 0.152.255.115.20's event has been collected
2017-05-07 19:15:38,929 Notify 0.152.255.115.20 event in 15 min
2017-05-07 19:16:01,139 Retransmission, Message ID: 38284.
2017-05-07 19:16:01,419 0.152.255.115.20 has logged in
2017-05-07 19:16:01,427 file_cache is unavailable when using oauth2client >= 4.0.0
Traceback (most recent call last):
  File "/usr/local/lib/python3.6/site-packages/googleapiclient/discovery_cache/__init__.py", line 36, in autodetect
    from google.appengine.api import memcache
ModuleNotFoundError: No module named 'google'

During handling of the above exception, another exception occurred:

Traceback (most recent call last):
  File "/usr/local/lib/python3.6/site-packages/googleapiclient/discovery_cache/file_cache.py", line 33, in <module>
    from oauth2client.contrib.locked_file import LockedFile
ModuleNotFoundError: No module named 'oauth2client.contrib.locked_file'

During handling of the above exception, another exception occurred:

Traceback (most recent call last):
  File "/usr/local/lib/python3.6/site-packages/googleapiclient/discovery_cache/file_cache.py", line 37, in <module>
    from oauth2client.locked_file import LockedFile
ModuleNotFoundError: No module named 'oauth2client.locked_file'

During handling of the above exception, another exception occurred:

Traceback (most recent call last):
  File "/usr/local/lib/python3.6/site-packages/googleapiclient/discovery_cache/__init__.py", line 41, in autodetect
    from . import file_cache
  File "/usr/local/lib/python3.6/site-packages/googleapiclient/discovery_cache/file_cache.py", line 41, in <module>
    'file_cache is unavailable when using oauth2client >= 4.0.0')
ImportError: file_cache is unavailable when using oauth2client >= 4.0.0
2017-05-07 19:16:01,429 URL being requested: GET https://www.googleapis.com/discovery/v1/apis/calendar/v3/rest
2017-05-07 19:16:01,593 URL being requested: GET https://www.googleapis.com/calendar/v3/calendars/primary/events?timeMin=2017-05-07T23%3A16%3A01.561031Z&maxResults=10&singleEvents=true&orderBy=startTime&alt=json
2017-05-07 19:16:01,725 0.152.255.115.20's event has been collected
2017-05-07 19:16:01,742 Notify 0.152.255.115.20 event in 16 min
2017-05-07 19:17:21,531 0.152.255.115.20 has logged in
2017-05-07 19:17:21,540 file_cache is unavailable when using oauth2client >= 4.0.0
Traceback (most recent call last):
  File "/usr/local/lib/python3.6/site-packages/googleapiclient/discovery_cache/__init__.py", line 36, in autodetect
    from google.appengine.api import memcache
ModuleNotFoundError: No module named 'google'

During handling of the above exception, another exception occurred:

Traceback (most recent call last):
  File "/usr/local/lib/python3.6/site-packages/googleapiclient/discovery_cache/file_cache.py", line 33, in <module>
    from oauth2client.contrib.locked_file import LockedFile
ModuleNotFoundError: No module named 'oauth2client.contrib.locked_file'

During handling of the above exception, another exception occurred:

Traceback (most recent call last):
  File "/usr/local/lib/python3.6/site-packages/googleapiclient/discovery_cache/file_cache.py", line 37, in <module>
    from oauth2client.locked_file import LockedFile
ModuleNotFoundError: No module named 'oauth2client.locked_file'

During handling of the above exception, another exception occurred:

Traceback (most recent call last):
  File "/usr/local/lib/python3.6/site-packages/googleapiclient/discovery_cache/__init__.py", line 41, in autodetect
    from . import file_cache
  File "/usr/local/lib/python3.6/site-packages/googleapiclient/discovery_cache/file_cache.py", line 41, in <module>
    'file_cache is unavailable when using oauth2client >= 4.0.0')
ImportError: file_cache is unavailable when using oauth2client >= 4.0.0
2017-05-07 19:17:21,542 URL being requested: GET https://www.googleapis.com/discovery/v1/apis/calendar/v3/rest
2017-05-07 19:17:21,710 URL being requested: GET https://www.googleapis.com/calendar/v3/calendars/primary/events?timeMin=2017-05-07T23%3A17%3A21.678536Z&maxResults=10&singleEvents=true&orderBy=startTime&alt=json
2017-05-07 19:17:21,799 0.152.255.115.20's event has been collected
2017-05-07 19:17:21,816 Notify 0.152.255.115.20 event in 17 min
