2017-05-07 21:10:24,519 211.127.98.139.69 has logged in
2017-05-07 21:13:52,037 211.127.98.139.69 has logged in
2017-05-07 21:25:30,836 211.127.98.139.69 has logged in
2017-05-07 21:26:47,418 211.127.98.139.69 has logged in
2017-05-07 21:27:45,565 211.127.98.139.69 has logged in
2017-05-07 21:28:29,215 211.127.98.139.69 has logged in
2017-05-07 21:29:25,825 211.127.98.139.69 has logged in
2017-05-07 21:29:25,853 file_cache is unavailable when using oauth2client >= 4.0.0
Traceback (most recent call last):
  File "/usr/local/lib/python3.6/site-packages/google_api_python_client-1.6.2-py3.6.egg/googleapiclient/discovery_cache/__init__.py", line 36, in autodetect
    from google.appengine.api import memcache
ModuleNotFoundError: No module named 'google'

During handling of the above exception, another exception occurred:

Traceback (most recent call last):
  File "/usr/local/lib/python3.6/site-packages/google_api_python_client-1.6.2-py3.6.egg/googleapiclient/discovery_cache/file_cache.py", line 33, in <module>
    from oauth2client.contrib.locked_file import LockedFile
ModuleNotFoundError: No module named 'oauth2client.contrib.locked_file'

During handling of the above exception, another exception occurred:

Traceback (most recent call last):
  File "/usr/local/lib/python3.6/site-packages/google_api_python_client-1.6.2-py3.6.egg/googleapiclient/discovery_cache/file_cache.py", line 37, in <module>
    from oauth2client.locked_file import LockedFile
ModuleNotFoundError: No module named 'oauth2client.locked_file'

During handling of the above exception, another exception occurred:

Traceback (most recent call last):
  File "/usr/local/lib/python3.6/site-packages/google_api_python_client-1.6.2-py3.6.egg/googleapiclient/discovery_cache/__init__.py", line 41, in autodetect
    from . import file_cache
  File "/usr/local/lib/python3.6/site-packages/google_api_python_client-1.6.2-py3.6.egg/googleapiclient/discovery_cache/file_cache.py", line 41, in <module>
    'file_cache is unavailable when using oauth2client >= 4.0.0')
ImportError: file_cache is unavailable when using oauth2client >= 4.0.0
2017-05-07 21:29:25,856 URL being requested: GET https://www.googleapis.com/discovery/v1/apis/calendar/v3/rest
2017-05-07 21:29:26,081 URL being requested: GET https://www.googleapis.com/calendar/v3/calendars/primary/events?timeMin=2017-05-07T21%3A29%3A26.050841Z&maxResults=10&singleEvents=true&orderBy=startTime&alt=json
2017-05-07 21:29:26,127 Refreshing due to a 401 (attempt 1/2)
2017-05-07 21:29:26,128 Refreshing access_token
2017-05-07 21:29:26,418 211.127.98.139.69's event has been collected
2017-05-07 21:30:04,968 211.127.98.139.69 has logged in
2017-05-07 21:30:04,988 file_cache is unavailable when using oauth2client >= 4.0.0
Traceback (most recent call last):
  File "/usr/local/lib/python3.6/site-packages/google_api_python_client-1.6.2-py3.6.egg/googleapiclient/discovery_cache/__init__.py", line 36, in autodetect
    from google.appengine.api import memcache
ModuleNotFoundError: No module named 'google'

During handling of the above exception, another exception occurred:

Traceback (most recent call last):
  File "/usr/local/lib/python3.6/site-packages/google_api_python_client-1.6.2-py3.6.egg/googleapiclient/discovery_cache/file_cache.py", line 33, in <module>
    from oauth2client.contrib.locked_file import LockedFile
ModuleNotFoundError: No module named 'oauth2client.contrib.locked_file'

During handling of the above exception, another exception occurred:

Traceback (most recent call last):
  File "/usr/local/lib/python3.6/site-packages/google_api_python_client-1.6.2-py3.6.egg/googleapiclient/discovery_cache/file_cache.py", line 37, in <module>
    from oauth2client.locked_file import LockedFile
ModuleNotFoundError: No module named 'oauth2client.locked_file'

During handling of the above exception, another exception occurred:

Traceback (most recent call last):
  File "/usr/local/lib/python3.6/site-packages/google_api_python_client-1.6.2-py3.6.egg/googleapiclient/discovery_cache/__init__.py", line 41, in autodetect
    from . import file_cache
  File "/usr/local/lib/python3.6/site-packages/google_api_python_client-1.6.2-py3.6.egg/googleapiclient/discovery_cache/file_cache.py", line 41, in <module>
    'file_cache is unavailable when using oauth2client >= 4.0.0')
ImportError: file_cache is unavailable when using oauth2client >= 4.0.0
2017-05-07 21:30:05,004 URL being requested: GET https://www.googleapis.com/discovery/v1/apis/calendar/v3/rest
2017-05-07 21:37:18,637 211.127.98.139.69 has logged in
2017-05-07 21:37:18,657 file_cache is unavailable when using oauth2client >= 4.0.0
Traceback (most recent call last):
  File "/usr/local/lib/python3.6/site-packages/google_api_python_client-1.6.2-py3.6.egg/googleapiclient/discovery_cache/__init__.py", line 36, in autodetect
    from google.appengine.api import memcache
ModuleNotFoundError: No module named 'google'

During handling of the above exception, another exception occurred:

Traceback (most recent call last):
  File "/usr/local/lib/python3.6/site-packages/google_api_python_client-1.6.2-py3.6.egg/googleapiclient/discovery_cache/file_cache.py", line 33, in <module>
    from oauth2client.contrib.locked_file import LockedFile
ModuleNotFoundError: No module named 'oauth2client.contrib.locked_file'

During handling of the above exception, another exception occurred:

Traceback (most recent call last):
  File "/usr/local/lib/python3.6/site-packages/google_api_python_client-1.6.2-py3.6.egg/googleapiclient/discovery_cache/file_cache.py", line 37, in <module>
    from oauth2client.locked_file import LockedFile
ModuleNotFoundError: No module named 'oauth2client.locked_file'

During handling of the above exception, another exception occurred:

Traceback (most recent call last):
  File "/usr/local/lib/python3.6/site-packages/google_api_python_client-1.6.2-py3.6.egg/googleapiclient/discovery_cache/__init__.py", line 41, in autodetect
    from . import file_cache
  File "/usr/local/lib/python3.6/site-packages/google_api_python_client-1.6.2-py3.6.egg/googleapiclient/discovery_cache/file_cache.py", line 41, in <module>
    'file_cache is unavailable when using oauth2client >= 4.0.0')
ImportError: file_cache is unavailable when using oauth2client >= 4.0.0
2017-05-07 21:37:18,659 URL being requested: GET https://www.googleapis.com/discovery/v1/apis/calendar/v3/rest
2017-05-07 21:37:18,813 URL being requested: GET https://www.googleapis.com/calendar/v3/calendars/primary/events?timeMin=2017-05-07T21%3A37%3A18.782402Z&maxResults=10&singleEvents=true&orderBy=startTime&alt=json
2017-05-07 21:37:18,860 Refreshing due to a 401 (attempt 1/2)
2017-05-07 21:37:18,861 Refreshing access_token
2017-05-07 21:37:19,138 211.127.98.139.69's event has been collected
2017-05-07 21:55:11,523 211.127.98.139.69 has logged in
2017-05-07 21:55:11,545 file_cache is unavailable when using oauth2client >= 4.0.0
Traceback (most recent call last):
  File "/usr/local/lib/python3.6/site-packages/google_api_python_client-1.6.2-py3.6.egg/googleapiclient/discovery_cache/__init__.py", line 36, in autodetect
    from google.appengine.api import memcache
ModuleNotFoundError: No module named 'google'

During handling of the above exception, another exception occurred:

Traceback (most recent call last):
  File "/usr/local/lib/python3.6/site-packages/google_api_python_client-1.6.2-py3.6.egg/googleapiclient/discovery_cache/file_cache.py", line 33, in <module>
    from oauth2client.contrib.locked_file import LockedFile
ModuleNotFoundError: No module named 'oauth2client.contrib.locked_file'

During handling of the above exception, another exception occurred:

Traceback (most recent call last):
  File "/usr/local/lib/python3.6/site-packages/google_api_python_client-1.6.2-py3.6.egg/googleapiclient/discovery_cache/file_cache.py", line 37, in <module>
    from oauth2client.locked_file import LockedFile
ModuleNotFoundError: No module named 'oauth2client.locked_file'

During handling of the above exception, another exception occurred:

Traceback (most recent call last):
  File "/usr/local/lib/python3.6/site-packages/google_api_python_client-1.6.2-py3.6.egg/googleapiclient/discovery_cache/__init__.py", line 41, in autodetect
    from . import file_cache
  File "/usr/local/lib/python3.6/site-packages/google_api_python_client-1.6.2-py3.6.egg/googleapiclient/discovery_cache/file_cache.py", line 41, in <module>
    'file_cache is unavailable when using oauth2client >= 4.0.0')
ImportError: file_cache is unavailable when using oauth2client >= 4.0.0
2017-05-07 21:55:11,548 URL being requested: GET https://www.googleapis.com/discovery/v1/apis/calendar/v3/rest
2017-05-07 21:55:11,728 URL being requested: GET https://www.googleapis.com/calendar/v3/calendars/primary/events?timeMin=2017-05-07T21%3A55%3A11.698919Z&maxResults=10&singleEvents=true&orderBy=startTime&alt=json
2017-05-07 21:55:11,789 Refreshing due to a 401 (attempt 1/2)
2017-05-07 21:55:11,790 Refreshing access_token
2017-05-07 21:55:12,193 211.127.98.139.69's event has been collected
2017-05-07 21:56:10,712 211.127.98.139.69 has logged in
2017-05-07 21:56:10,734 file_cache is unavailable when using oauth2client >= 4.0.0
Traceback (most recent call last):
  File "/usr/local/lib/python3.6/site-packages/google_api_python_client-1.6.2-py3.6.egg/googleapiclient/discovery_cache/__init__.py", line 36, in autodetect
    from google.appengine.api import memcache
ModuleNotFoundError: No module named 'google'

During handling of the above exception, another exception occurred:

Traceback (most recent call last):
  File "/usr/local/lib/python3.6/site-packages/google_api_python_client-1.6.2-py3.6.egg/googleapiclient/discovery_cache/file_cache.py", line 33, in <module>
    from oauth2client.contrib.locked_file import LockedFile
ModuleNotFoundError: No module named 'oauth2client.contrib.locked_file'

During handling of the above exception, another exception occurred:

Traceback (most recent call last):
  File "/usr/local/lib/python3.6/site-packages/google_api_python_client-1.6.2-py3.6.egg/googleapiclient/discovery_cache/file_cache.py", line 37, in <module>
    from oauth2client.locked_file import LockedFile
ModuleNotFoundError: No module named 'oauth2client.locked_file'

During handling of the above exception, another exception occurred:

Traceback (most recent call last):
  File "/usr/local/lib/python3.6/site-packages/google_api_python_client-1.6.2-py3.6.egg/googleapiclient/discovery_cache/__init__.py", line 41, in autodetect
    from . import file_cache
  File "/usr/local/lib/python3.6/site-packages/google_api_python_client-1.6.2-py3.6.egg/googleapiclient/discovery_cache/file_cache.py", line 41, in <module>
    'file_cache is unavailable when using oauth2client >= 4.0.0')
ImportError: file_cache is unavailable when using oauth2client >= 4.0.0
2017-05-07 21:56:10,737 URL being requested: GET https://www.googleapis.com/discovery/v1/apis/calendar/v3/rest
2017-05-07 21:56:10,903 URL being requested: GET https://www.googleapis.com/calendar/v3/calendars/primary/events?timeMin=2017-05-07T21%3A56%3A10.873203Z&maxResults=10&singleEvents=true&orderBy=startTime&alt=json
2017-05-07 21:56:10,948 Refreshing due to a 401 (attempt 1/2)
2017-05-07 21:56:10,949 Refreshing access_token
2017-05-07 21:56:11,256 211.127.98.139.69's event has been collected
2017-05-07 21:57:10,813 211.127.98.139.69 has logged in
2017-05-07 21:57:10,833 file_cache is unavailable when using oauth2client >= 4.0.0
Traceback (most recent call last):
  File "/usr/local/lib/python3.6/site-packages/google_api_python_client-1.6.2-py3.6.egg/googleapiclient/discovery_cache/__init__.py", line 36, in autodetect
    from google.appengine.api import memcache
ModuleNotFoundError: No module named 'google'

During handling of the above exception, another exception occurred:

Traceback (most recent call last):
  File "/usr/local/lib/python3.6/site-packages/google_api_python_client-1.6.2-py3.6.egg/googleapiclient/discovery_cache/file_cache.py", line 33, in <module>
    from oauth2client.contrib.locked_file import LockedFile
ModuleNotFoundError: No module named 'oauth2client.contrib.locked_file'

During handling of the above exception, another exception occurred:

Traceback (most recent call last):
  File "/usr/local/lib/python3.6/site-packages/google_api_python_client-1.6.2-py3.6.egg/googleapiclient/discovery_cache/file_cache.py", line 37, in <module>
    from oauth2client.locked_file import LockedFile
ModuleNotFoundError: No module named 'oauth2client.locked_file'

During handling of the above exception, another exception occurred:

Traceback (most recent call last):
  File "/usr/local/lib/python3.6/site-packages/google_api_python_client-1.6.2-py3.6.egg/googleapiclient/discovery_cache/__init__.py", line 41, in autodetect
    from . import file_cache
  File "/usr/local/lib/python3.6/site-packages/google_api_python_client-1.6.2-py3.6.egg/googleapiclient/discovery_cache/file_cache.py", line 41, in <module>
    'file_cache is unavailable when using oauth2client >= 4.0.0')
ImportError: file_cache is unavailable when using oauth2client >= 4.0.0
2017-05-07 21:57:10,835 URL being requested: GET https://www.googleapis.com/discovery/v1/apis/calendar/v3/rest
2017-05-07 21:57:10,993 URL being requested: GET https://www.googleapis.com/calendar/v3/calendars/primary/events?timeMin=2017-05-07T21%3A57%3A10.964093Z&maxResults=10&singleEvents=true&orderBy=startTime&alt=json
2017-05-07 21:57:11,061 Refreshing due to a 401 (attempt 1/2)
2017-05-07 21:57:11,062 Refreshing access_token
2017-05-07 21:57:11,344 211.127.98.139.69's event has been collected
2017-05-07 21:57:24,637 211.127.98.139.69 has logged in
2017-05-07 21:57:24,656 file_cache is unavailable when using oauth2client >= 4.0.0
Traceback (most recent call last):
  File "/usr/local/lib/python3.6/site-packages/google_api_python_client-1.6.2-py3.6.egg/googleapiclient/discovery_cache/__init__.py", line 36, in autodetect
    from google.appengine.api import memcache
ModuleNotFoundError: No module named 'google'

During handling of the above exception, another exception occurred:

Traceback (most recent call last):
  File "/usr/local/lib/python3.6/site-packages/google_api_python_client-1.6.2-py3.6.egg/googleapiclient/discovery_cache/file_cache.py", line 33, in <module>
    from oauth2client.contrib.locked_file import LockedFile
ModuleNotFoundError: No module named 'oauth2client.contrib.locked_file'

During handling of the above exception, another exception occurred:

Traceback (most recent call last):
  File "/usr/local/lib/python3.6/site-packages/google_api_python_client-1.6.2-py3.6.egg/googleapiclient/discovery_cache/file_cache.py", line 37, in <module>
    from oauth2client.locked_file import LockedFile
ModuleNotFoundError: No module named 'oauth2client.locked_file'

During handling of the above exception, another exception occurred:

Traceback (most recent call last):
  File "/usr/local/lib/python3.6/site-packages/google_api_python_client-1.6.2-py3.6.egg/googleapiclient/discovery_cache/__init__.py", line 41, in autodetect
    from . import file_cache
  File "/usr/local/lib/python3.6/site-packages/google_api_python_client-1.6.2-py3.6.egg/googleapiclient/discovery_cache/file_cache.py", line 41, in <module>
    'file_cache is unavailable when using oauth2client >= 4.0.0')
ImportError: file_cache is unavailable when using oauth2client >= 4.0.0
2017-05-07 21:57:24,659 URL being requested: GET https://www.googleapis.com/discovery/v1/apis/calendar/v3/rest
2017-05-07 21:57:24,821 URL being requested: GET https://www.googleapis.com/calendar/v3/calendars/primary/events?timeMin=2017-05-07T21%3A57%3A24.791593Z&maxResults=10&singleEvents=true&orderBy=startTime&alt=json
2017-05-07 21:57:24,857 Refreshing due to a 401 (attempt 1/2)
2017-05-07 21:57:24,857 Refreshing access_token
2017-05-07 21:57:25,107 211.127.98.139.69's event has been collected
2017-05-07 22:00:24,984 211.127.98.139.69 has logged in
2017-05-07 22:00:25,005 file_cache is unavailable when using oauth2client >= 4.0.0
Traceback (most recent call last):
  File "/usr/local/lib/python3.6/site-packages/google_api_python_client-1.6.2-py3.6.egg/googleapiclient/discovery_cache/__init__.py", line 36, in autodetect
    from google.appengine.api import memcache
ModuleNotFoundError: No module named 'google'

During handling of the above exception, another exception occurred:

Traceback (most recent call last):
  File "/usr/local/lib/python3.6/site-packages/google_api_python_client-1.6.2-py3.6.egg/googleapiclient/discovery_cache/file_cache.py", line 33, in <module>
    from oauth2client.contrib.locked_file import LockedFile
ModuleNotFoundError: No module named 'oauth2client.contrib.locked_file'

During handling of the above exception, another exception occurred:

Traceback (most recent call last):
  File "/usr/local/lib/python3.6/site-packages/google_api_python_client-1.6.2-py3.6.egg/googleapiclient/discovery_cache/file_cache.py", line 37, in <module>
    from oauth2client.locked_file import LockedFile
ModuleNotFoundError: No module named 'oauth2client.locked_file'

During handling of the above exception, another exception occurred:

Traceback (most recent call last):
  File "/usr/local/lib/python3.6/site-packages/google_api_python_client-1.6.2-py3.6.egg/googleapiclient/discovery_cache/__init__.py", line 41, in autodetect
    from . import file_cache
  File "/usr/local/lib/python3.6/site-packages/google_api_python_client-1.6.2-py3.6.egg/googleapiclient/discovery_cache/file_cache.py", line 41, in <module>
    'file_cache is unavailable when using oauth2client >= 4.0.0')
ImportError: file_cache is unavailable when using oauth2client >= 4.0.0
2017-05-07 22:00:25,008 URL being requested: GET https://www.googleapis.com/discovery/v1/apis/calendar/v3/rest
2017-05-07 22:00:25,170 URL being requested: GET https://www.googleapis.com/calendar/v3/calendars/primary/events?timeMin=2017-05-07T22%3A00%3A25.139236Z&maxResults=10&singleEvents=true&orderBy=startTime&alt=json
2017-05-07 22:00:25,225 Refreshing due to a 401 (attempt 1/2)
2017-05-07 22:00:25,226 Refreshing access_token
2017-05-07 22:00:25,568 211.127.98.139.69's event has been collected
2017-05-07 22:00:25,585 Notify 211.127.98.139.69 event in -30 min
2017-05-07 22:01:51,745 211.127.98.139.69 has logged in
2017-05-07 22:01:51,765 file_cache is unavailable when using oauth2client >= 4.0.0
Traceback (most recent call last):
  File "/usr/local/lib/python3.6/site-packages/google_api_python_client-1.6.2-py3.6.egg/googleapiclient/discovery_cache/__init__.py", line 36, in autodetect
    from google.appengine.api import memcache
ModuleNotFoundError: No module named 'google'

During handling of the above exception, another exception occurred:

Traceback (most recent call last):
  File "/usr/local/lib/python3.6/site-packages/google_api_python_client-1.6.2-py3.6.egg/googleapiclient/discovery_cache/file_cache.py", line 33, in <module>
    from oauth2client.contrib.locked_file import LockedFile
ModuleNotFoundError: No module named 'oauth2client.contrib.locked_file'

During handling of the above exception, another exception occurred:

Traceback (most recent call last):
  File "/usr/local/lib/python3.6/site-packages/google_api_python_client-1.6.2-py3.6.egg/googleapiclient/discovery_cache/file_cache.py", line 37, in <module>
    from oauth2client.locked_file import LockedFile
ModuleNotFoundError: No module named 'oauth2client.locked_file'

During handling of the above exception, another exception occurred:

Traceback (most recent call last):
  File "/usr/local/lib/python3.6/site-packages/google_api_python_client-1.6.2-py3.6.egg/googleapiclient/discovery_cache/__init__.py", line 41, in autodetect
    from . import file_cache
  File "/usr/local/lib/python3.6/site-packages/google_api_python_client-1.6.2-py3.6.egg/googleapiclient/discovery_cache/file_cache.py", line 41, in <module>
    'file_cache is unavailable when using oauth2client >= 4.0.0')
ImportError: file_cache is unavailable when using oauth2client >= 4.0.0
2017-05-07 22:01:51,768 URL being requested: GET https://www.googleapis.com/discovery/v1/apis/calendar/v3/rest
2017-05-07 22:01:51,933 URL being requested: GET https://www.googleapis.com/calendar/v3/calendars/primary/events?timeMin=2017-05-07T22%3A01%3A51.902502Z&maxResults=10&singleEvents=true&orderBy=startTime&alt=json
2017-05-07 22:01:51,969 Refreshing due to a 401 (attempt 1/2)
2017-05-07 22:01:51,970 Refreshing access_token
2017-05-07 22:01:52,253 211.127.98.139.69's event has been collected
2017-05-07 22:01:52,270 Notify 211.127.98.139.69 event in -29 min
2017-05-07 22:03:26,633 211.127.98.139.69 has logged in
2017-05-07 22:03:26,652 file_cache is unavailable when using oauth2client >= 4.0.0
Traceback (most recent call last):
  File "/usr/local/lib/python3.6/site-packages/google_api_python_client-1.6.2-py3.6.egg/googleapiclient/discovery_cache/__init__.py", line 36, in autodetect
    from google.appengine.api import memcache
ModuleNotFoundError: No module named 'google'

During handling of the above exception, another exception occurred:

Traceback (most recent call last):
  File "/usr/local/lib/python3.6/site-packages/google_api_python_client-1.6.2-py3.6.egg/googleapiclient/discovery_cache/file_cache.py", line 33, in <module>
    from oauth2client.contrib.locked_file import LockedFile
ModuleNotFoundError: No module named 'oauth2client.contrib.locked_file'

During handling of the above exception, another exception occurred:

Traceback (most recent call last):
  File "/usr/local/lib/python3.6/site-packages/google_api_python_client-1.6.2-py3.6.egg/googleapiclient/discovery_cache/file_cache.py", line 37, in <module>
    from oauth2client.locked_file import LockedFile
ModuleNotFoundError: No module named 'oauth2client.locked_file'

During handling of the above exception, another exception occurred:

Traceback (most recent call last):
  File "/usr/local/lib/python3.6/site-packages/google_api_python_client-1.6.2-py3.6.egg/googleapiclient/discovery_cache/__init__.py", line 41, in autodetect
    from . import file_cache
  File "/usr/local/lib/python3.6/site-packages/google_api_python_client-1.6.2-py3.6.egg/googleapiclient/discovery_cache/file_cache.py", line 41, in <module>
    'file_cache is unavailable when using oauth2client >= 4.0.0')
ImportError: file_cache is unavailable when using oauth2client >= 4.0.0
2017-05-07 22:03:26,654 URL being requested: GET https://www.googleapis.com/discovery/v1/apis/calendar/v3/rest
2017-05-07 22:03:26,811 URL being requested: GET https://www.googleapis.com/calendar/v3/calendars/primary/events?timeMin=2017-05-07T22%3A03%3A26.782380Z&maxResults=10&singleEvents=true&orderBy=startTime&alt=json
2017-05-07 22:03:26,872 Refreshing due to a 401 (attempt 1/2)
2017-05-07 22:03:26,873 Refreshing access_token
2017-05-07 22:03:27,132 211.127.98.139.69's event has been collected
2017-05-07 22:03:27,149 Notify 211.127.98.139.69 event in -27 min
2017-05-07 22:04:31,888 211.127.98.139.69 has logged in
2017-05-07 22:04:31,907 file_cache is unavailable when using oauth2client >= 4.0.0
Traceback (most recent call last):
  File "/usr/local/lib/python3.6/site-packages/google_api_python_client-1.6.2-py3.6.egg/googleapiclient/discovery_cache/__init__.py", line 36, in autodetect
    from google.appengine.api import memcache
ModuleNotFoundError: No module named 'google'

During handling of the above exception, another exception occurred:

Traceback (most recent call last):
  File "/usr/local/lib/python3.6/site-packages/google_api_python_client-1.6.2-py3.6.egg/googleapiclient/discovery_cache/file_cache.py", line 33, in <module>
    from oauth2client.contrib.locked_file import LockedFile
ModuleNotFoundError: No module named 'oauth2client.contrib.locked_file'

During handling of the above exception, another exception occurred:

Traceback (most recent call last):
  File "/usr/local/lib/python3.6/site-packages/google_api_python_client-1.6.2-py3.6.egg/googleapiclient/discovery_cache/file_cache.py", line 37, in <module>
    from oauth2client.locked_file import LockedFile
ModuleNotFoundError: No module named 'oauth2client.locked_file'

During handling of the above exception, another exception occurred:

Traceback (most recent call last):
  File "/usr/local/lib/python3.6/site-packages/google_api_python_client-1.6.2-py3.6.egg/googleapiclient/discovery_cache/__init__.py", line 41, in autodetect
    from . import file_cache
  File "/usr/local/lib/python3.6/site-packages/google_api_python_client-1.6.2-py3.6.egg/googleapiclient/discovery_cache/file_cache.py", line 41, in <module>
    'file_cache is unavailable when using oauth2client >= 4.0.0')
ImportError: file_cache is unavailable when using oauth2client >= 4.0.0
2017-05-07 22:04:31,910 URL being requested: GET https://www.googleapis.com/discovery/v1/apis/calendar/v3/rest
2017-05-07 22:04:32,073 URL being requested: GET https://www.googleapis.com/calendar/v3/calendars/primary/events?timeMin=2017-05-07T22%3A04%3A32.043274Z&maxResults=10&singleEvents=true&orderBy=startTime&alt=json
2017-05-07 22:04:32,110 Refreshing due to a 401 (attempt 1/2)
2017-05-07 22:04:32,111 Refreshing access_token
2017-05-07 22:04:32,415 211.127.98.139.69's event has been collected
2017-05-07 22:04:32,431 Notify 211.127.98.139.69 event in -26 min
2017-05-07 22:05:39,116 211.127.98.139.69 has logged in
2017-05-07 22:05:39,137 file_cache is unavailable when using oauth2client >= 4.0.0
Traceback (most recent call last):
  File "/usr/local/lib/python3.6/site-packages/google_api_python_client-1.6.2-py3.6.egg/googleapiclient/discovery_cache/__init__.py", line 36, in autodetect
    from google.appengine.api import memcache
ModuleNotFoundError: No module named 'google'

During handling of the above exception, another exception occurred:

Traceback (most recent call last):
  File "/usr/local/lib/python3.6/site-packages/google_api_python_client-1.6.2-py3.6.egg/googleapiclient/discovery_cache/file_cache.py", line 33, in <module>
    from oauth2client.contrib.locked_file import LockedFile
ModuleNotFoundError: No module named 'oauth2client.contrib.locked_file'

During handling of the above exception, another exception occurred:

Traceback (most recent call last):
  File "/usr/local/lib/python3.6/site-packages/google_api_python_client-1.6.2-py3.6.egg/googleapiclient/discovery_cache/file_cache.py", line 37, in <module>
    from oauth2client.locked_file import LockedFile
ModuleNotFoundError: No module named 'oauth2client.locked_file'

During handling of the above exception, another exception occurred:

Traceback (most recent call last):
  File "/usr/local/lib/python3.6/site-packages/google_api_python_client-1.6.2-py3.6.egg/googleapiclient/discovery_cache/__init__.py", line 41, in autodetect
    from . import file_cache
  File "/usr/local/lib/python3.6/site-packages/google_api_python_client-1.6.2-py3.6.egg/googleapiclient/discovery_cache/file_cache.py", line 41, in <module>
    'file_cache is unavailable when using oauth2client >= 4.0.0')
ImportError: file_cache is unavailable when using oauth2client >= 4.0.0
2017-05-07 22:05:39,139 URL being requested: GET https://www.googleapis.com/discovery/v1/apis/calendar/v3/rest
2017-05-07 22:05:39,289 URL being requested: GET https://www.googleapis.com/calendar/v3/calendars/primary/events?timeMin=2017-05-07T22%3A05%3A39.259278Z&maxResults=10&singleEvents=true&orderBy=startTime&alt=json
2017-05-07 22:05:39,356 Refreshing due to a 401 (attempt 1/2)
2017-05-07 22:05:39,357 Refreshing access_token
2017-05-07 22:05:39,837 211.127.98.139.69's event has been collected
2017-05-07 22:05:39,854 Notify 211.127.98.139.69 event in -25 min
2017-05-07 18:40:25,828 Retransmission, Message ID: 15485.
2017-05-07 19:15:38,488 0.152.255.115.20 has logged in
2017-05-07 19:15:38,511 file_cache is unavailable when using oauth2client >= 4.0.0
Traceback (most recent call last):
  File "/usr/local/lib/python3.6/site-packages/googleapiclient/discovery_cache/__init__.py", line 36, in autodetect
    from google.appengine.api import memcache
ModuleNotFoundError: No module named 'google'

During handling of the above exception, another exception occurred:

Traceback (most recent call last):
  File "/usr/local/lib/python3.6/site-packages/googleapiclient/discovery_cache/file_cache.py", line 33, in <module>
    from oauth2client.contrib.locked_file import LockedFile
ModuleNotFoundError: No module named 'oauth2client.contrib.locked_file'

During handling of the above exception, another exception occurred:

Traceback (most recent call last):
  File "/usr/local/lib/python3.6/site-packages/googleapiclient/discovery_cache/file_cache.py", line 37, in <module>
    from oauth2client.locked_file import LockedFile
ModuleNotFoundError: No module named 'oauth2client.locked_file'

During handling of the above exception, another exception occurred:

Traceback (most recent call last):
  File "/usr/local/lib/python3.6/site-packages/googleapiclient/discovery_cache/__init__.py", line 41, in autodetect
    from . import file_cache
  File "/usr/local/lib/python3.6/site-packages/googleapiclient/discovery_cache/file_cache.py", line 41, in <module>
    'file_cache is unavailable when using oauth2client >= 4.0.0')
ImportError: file_cache is unavailable when using oauth2client >= 4.0.0
2017-05-07 19:15:38,515 URL being requested: GET https://www.googleapis.com/discovery/v1/apis/calendar/v3/rest
2017-05-07 19:15:38,673 URL being requested: GET https://www.googleapis.com/calendar/v3/calendars/primary/events?timeMin=2017-05-07T23%3A15%3A38.640549Z&maxResults=10&singleEvents=true&orderBy=startTime&alt=json
2017-05-07 19:15:38,912 0.152.255.115.20's event has been collected
2017-05-07 19:15:38,929 Notify 0.152.255.115.20 event in 15 min
2017-05-07 19:16:01,139 Retransmission, Message ID: 38284.
2017-05-07 19:16:01,419 0.152.255.115.20 has logged in
2017-05-07 19:16:01,427 file_cache is unavailable when using oauth2client >= 4.0.0
Traceback (most recent call last):
  File "/usr/local/lib/python3.6/site-packages/googleapiclient/discovery_cache/__init__.py", line 36, in autodetect
    from google.appengine.api import memcache
ModuleNotFoundError: No module named 'google'

During handling of the above exception, another exception occurred:

Traceback (most recent call last):
  File "/usr/local/lib/python3.6/site-packages/googleapiclient/discovery_cache/file_cache.py", line 33, in <module>
    from oauth2client.contrib.locked_file import LockedFile
ModuleNotFoundError: No module named 'oauth2client.contrib.locked_file'

During handling of the above exception, another exception occurred:

Traceback (most recent call last):
  File "/usr/local/lib/python3.6/site-packages/googleapiclient/discovery_cache/file_cache.py", line 37, in <module>
    from oauth2client.locked_file import LockedFile
ModuleNotFoundError: No module named 'oauth2client.locked_file'

During handling of the above exception, another exception occurred:

Traceback (most recent call last):
  File "/usr/local/lib/python3.6/site-packages/googleapiclient/discovery_cache/__init__.py", line 41, in autodetect
    from . import file_cache
  File "/usr/local/lib/python3.6/site-packages/googleapiclient/discovery_cache/file_cache.py", line 41, in <module>
    'file_cache is unavailable when using oauth2client >= 4.0.0')
ImportError: file_cache is unavailable when using oauth2client >= 4.0.0
2017-05-07 19:16:01,429 URL being requested: GET https://www.googleapis.com/discovery/v1/apis/calendar/v3/rest
2017-05-07 19:16:01,593 URL being requested: GET https://www.googleapis.com/calendar/v3/calendars/primary/events?timeMin=2017-05-07T23%3A16%3A01.561031Z&maxResults=10&singleEvents=true&orderBy=startTime&alt=json
2017-05-07 19:16:01,725 0.152.255.115.20's event has been collected
2017-05-07 19:16:01,742 Notify 0.152.255.115.20 event in 16 min
2017-05-07 19:17:21,531 0.152.255.115.20 has logged in
2017-05-07 19:17:21,540 file_cache is unavailable when using oauth2client >= 4.0.0
Traceback (most recent call last):
  File "/usr/local/lib/python3.6/site-packages/googleapiclient/discovery_cache/__init__.py", line 36, in autodetect
    from google.appengine.api import memcache
ModuleNotFoundError: No module named 'google'

During handling of the above exception, another exception occurred:

Traceback (most recent call last):
  File "/usr/local/lib/python3.6/site-packages/googleapiclient/discovery_cache/file_cache.py", line 33, in <module>
    from oauth2client.contrib.locked_file import LockedFile
ModuleNotFoundError: No module named 'oauth2client.contrib.locked_file'

During handling of the above exception, another exception occurred:

Traceback (most recent call last):
  File "/usr/local/lib/python3.6/site-packages/googleapiclient/discovery_cache/file_cache.py", line 37, in <module>
    from oauth2client.locked_file import LockedFile
ModuleNotFoundError: No module named 'oauth2client.locked_file'

During handling of the above exception, another exception occurred:

Traceback (most recent call last):
  File "/usr/local/lib/python3.6/site-packages/googleapiclient/discovery_cache/__init__.py", line 41, in autodetect
    from . import file_cache
  File "/usr/local/lib/python3.6/site-packages/googleapiclient/discovery_cache/file_cache.py", line 41, in <module>
    'file_cache is unavailable when using oauth2client >= 4.0.0')
ImportError: file_cache is unavailable when using oauth2client >= 4.0.0
2017-05-07 19:17:21,542 URL being requested: GET https://www.googleapis.com/discovery/v1/apis/calendar/v3/rest
2017-05-07 19:17:21,710 URL being requested: GET https://www.googleapis.com/calendar/v3/calendars/primary/events?timeMin=2017-05-07T23%3A17%3A21.678536Z&maxResults=10&singleEvents=true&orderBy=startTime&alt=json
2017-05-07 19:17:21,799 0.152.255.115.20's event has been collected
2017-05-07 19:17:21,816 Notify 0.152.255.115.20 event in 17 min
2017-05-08 00:12:58,482 0.152.255.115.20 has logged in
2017-05-08 00:12:58,501 file_cache is unavailable when using oauth2client >= 4.0.0
Traceback (most recent call last):
  File "/usr/local/lib/python3.6/site-packages/google_api_python_client-1.6.2-py3.6.egg/googleapiclient/discovery_cache/__init__.py", line 36, in autodetect
    from google.appengine.api import memcache
ModuleNotFoundError: No module named 'google'

During handling of the above exception, another exception occurred:

Traceback (most recent call last):
  File "/usr/local/lib/python3.6/site-packages/google_api_python_client-1.6.2-py3.6.egg/googleapiclient/discovery_cache/file_cache.py", line 33, in <module>
    from oauth2client.contrib.locked_file import LockedFile
ModuleNotFoundError: No module named 'oauth2client.contrib.locked_file'

During handling of the above exception, another exception occurred:

Traceback (most recent call last):
  File "/usr/local/lib/python3.6/site-packages/google_api_python_client-1.6.2-py3.6.egg/googleapiclient/discovery_cache/file_cache.py", line 37, in <module>
    from oauth2client.locked_file import LockedFile
ModuleNotFoundError: No module named 'oauth2client.locked_file'

During handling of the above exception, another exception occurred:

Traceback (most recent call last):
  File "/usr/local/lib/python3.6/site-packages/google_api_python_client-1.6.2-py3.6.egg/googleapiclient/discovery_cache/__init__.py", line 41, in autodetect
    from . import file_cache
  File "/usr/local/lib/python3.6/site-packages/google_api_python_client-1.6.2-py3.6.egg/googleapiclient/discovery_cache/file_cache.py", line 41, in <module>
    'file_cache is unavailable when using oauth2client >= 4.0.0')
ImportError: file_cache is unavailable when using oauth2client >= 4.0.0
2017-05-08 00:12:58,504 URL being requested: GET https://www.googleapis.com/discovery/v1/apis/calendar/v3/rest
2017-05-08 00:12:58,663 URL being requested: GET https://www.googleapis.com/calendar/v3/calendars/primary/events?timeMin=2017-05-08T00%3A12%3A58.633610Z&maxResults=10&singleEvents=true&orderBy=startTime&alt=json
2017-05-08 00:12:58,701 Refreshing due to a 401 (attempt 1/2)
2017-05-08 00:12:58,702 Refreshing access_token
2017-05-08 00:12:58,987 0.152.255.115.20's event has been collected
2017-05-08 00:14:04,392 0.152.255.115.20 has logged in
2017-05-08 00:14:04,411 file_cache is unavailable when using oauth2client >= 4.0.0
Traceback (most recent call last):
  File "/usr/local/lib/python3.6/site-packages/google_api_python_client-1.6.2-py3.6.egg/googleapiclient/discovery_cache/__init__.py", line 36, in autodetect
    from google.appengine.api import memcache
ModuleNotFoundError: No module named 'google'

During handling of the above exception, another exception occurred:

Traceback (most recent call last):
  File "/usr/local/lib/python3.6/site-packages/google_api_python_client-1.6.2-py3.6.egg/googleapiclient/discovery_cache/file_cache.py", line 33, in <module>
    from oauth2client.contrib.locked_file import LockedFile
ModuleNotFoundError: No module named 'oauth2client.contrib.locked_file'

During handling of the above exception, another exception occurred:

Traceback (most recent call last):
  File "/usr/local/lib/python3.6/site-packages/google_api_python_client-1.6.2-py3.6.egg/googleapiclient/discovery_cache/file_cache.py", line 37, in <module>
    from oauth2client.locked_file import LockedFile
ModuleNotFoundError: No module named 'oauth2client.locked_file'

During handling of the above exception, another exception occurred:

Traceback (most recent call last):
  File "/usr/local/lib/python3.6/site-packages/google_api_python_client-1.6.2-py3.6.egg/googleapiclient/discovery_cache/__init__.py", line 41, in autodetect
    from . import file_cache
  File "/usr/local/lib/python3.6/site-packages/google_api_python_client-1.6.2-py3.6.egg/googleapiclient/discovery_cache/file_cache.py", line 41, in <module>
    'file_cache is unavailable when using oauth2client >= 4.0.0')
ImportError: file_cache is unavailable when using oauth2client >= 4.0.0
2017-05-08 00:14:04,413 URL being requested: GET https://www.googleapis.com/discovery/v1/apis/calendar/v3/rest
2017-05-08 00:14:04,574 URL being requested: GET https://www.googleapis.com/calendar/v3/calendars/primary/events?timeMin=2017-05-08T00%3A14%3A04.544232Z&maxResults=10&singleEvents=true&orderBy=startTime&alt=json
2017-05-08 00:14:04,634 Refreshing due to a 401 (attempt 1/2)
2017-05-08 00:14:04,635 Refreshing access_token
2017-05-08 00:14:04,896 0.152.255.115.20's event has been collected
2017-05-08 00:14:25,841 Notify 0.152.255.115.20 event in 5 min
2017-05-08 00:15:42,932 211.127.98.139.69 tries to log in but has not registered yet
2017-05-08 00:15:44,096 0.152.255.115.20 has logged in
2017-05-08 00:15:44,117 file_cache is unavailable when using oauth2client >= 4.0.0
Traceback (most recent call last):
  File "/usr/local/lib/python3.6/site-packages/google_api_python_client-1.6.2-py3.6.egg/googleapiclient/discovery_cache/__init__.py", line 36, in autodetect
    from google.appengine.api import memcache
ModuleNotFoundError: No module named 'google'

During handling of the above exception, another exception occurred:

Traceback (most recent call last):
  File "/usr/local/lib/python3.6/site-packages/google_api_python_client-1.6.2-py3.6.egg/googleapiclient/discovery_cache/file_cache.py", line 33, in <module>
    from oauth2client.contrib.locked_file import LockedFile
ModuleNotFoundError: No module named 'oauth2client.contrib.locked_file'

During handling of the above exception, another exception occurred:

Traceback (most recent call last):
  File "/usr/local/lib/python3.6/site-packages/google_api_python_client-1.6.2-py3.6.egg/googleapiclient/discovery_cache/file_cache.py", line 37, in <module>
    from oauth2client.locked_file import LockedFile
ModuleNotFoundError: No module named 'oauth2client.locked_file'

During handling of the above exception, another exception occurred:

Traceback (most recent call last):
  File "/usr/local/lib/python3.6/site-packages/google_api_python_client-1.6.2-py3.6.egg/googleapiclient/discovery_cache/__init__.py", line 41, in autodetect
    from . import file_cache
  File "/usr/local/lib/python3.6/site-packages/google_api_python_client-1.6.2-py3.6.egg/googleapiclient/discovery_cache/file_cache.py", line 41, in <module>
    'file_cache is unavailable when using oauth2client >= 4.0.0')
ImportError: file_cache is unavailable when using oauth2client >= 4.0.0
2017-05-08 00:15:44,119 URL being requested: GET https://www.googleapis.com/discovery/v1/apis/calendar/v3/rest
2017-05-08 00:15:44,499 URL being requested: GET https://www.googleapis.com/calendar/v3/calendars/primary/events?timeMin=2017-05-08T00%3A15%3A44.469639Z&maxResults=10&singleEvents=true&orderBy=startTime&alt=json
2017-05-08 00:15:44,552 Refreshing due to a 401 (attempt 1/2)
2017-05-08 00:15:44,553 Refreshing access_token
2017-05-08 00:15:44,914 0.152.255.115.20's event has been collected
2017-05-08 00:16:00,129 Notify 0.152.255.115.20 event in 5 min
2017-05-08 00:18:31,608 0.152.255.115.20 has logged in
2017-05-08 00:18:31,626 file_cache is unavailable when using oauth2client >= 4.0.0
Traceback (most recent call last):
  File "/usr/local/lib/python3.6/site-packages/google_api_python_client-1.6.2-py3.6.egg/googleapiclient/discovery_cache/__init__.py", line 36, in autodetect
    from google.appengine.api import memcache
ModuleNotFoundError: No module named 'google'

During handling of the above exception, another exception occurred:

Traceback (most recent call last):
  File "/usr/local/lib/python3.6/site-packages/google_api_python_client-1.6.2-py3.6.egg/googleapiclient/discovery_cache/file_cache.py", line 33, in <module>
    from oauth2client.contrib.locked_file import LockedFile
ModuleNotFoundError: No module named 'oauth2client.contrib.locked_file'

During handling of the above exception, another exception occurred:

Traceback (most recent call last):
  File "/usr/local/lib/python3.6/site-packages/google_api_python_client-1.6.2-py3.6.egg/googleapiclient/discovery_cache/file_cache.py", line 37, in <module>
    from oauth2client.locked_file import LockedFile
ModuleNotFoundError: No module named 'oauth2client.locked_file'

During handling of the above exception, another exception occurred:

Traceback (most recent call last):
  File "/usr/local/lib/python3.6/site-packages/google_api_python_client-1.6.2-py3.6.egg/googleapiclient/discovery_cache/__init__.py", line 41, in autodetect
    from . import file_cache
  File "/usr/local/lib/python3.6/site-packages/google_api_python_client-1.6.2-py3.6.egg/googleapiclient/discovery_cache/file_cache.py", line 41, in <module>
    'file_cache is unavailable when using oauth2client >= 4.0.0')
ImportError: file_cache is unavailable when using oauth2client >= 4.0.0
2017-05-08 00:18:31,628 URL being requested: GET https://www.googleapis.com/discovery/v1/apis/calendar/v3/rest
2017-05-08 00:18:31,788 URL being requested: GET https://www.googleapis.com/calendar/v3/calendars/primary/events?timeMin=2017-05-08T00%3A18%3A31.759389Z&maxResults=10&singleEvents=true&orderBy=startTime&alt=json
2017-05-08 00:18:31,838 Refreshing due to a 401 (attempt 1/2)
2017-05-08 00:18:31,839 Refreshing access_token
2017-05-08 00:18:32,138 0.152.255.115.20's event has been collected
2017-05-08 00:18:48,065 Notify 0.152.255.115.20 event in 5 min
2017-05-08 00:20:48,108 file_cache is unavailable when using oauth2client >= 4.0.0
Traceback (most recent call last):
  File "/usr/local/lib/python3.6/site-packages/google_api_python_client-1.6.2-py3.6.egg/googleapiclient/discovery_cache/__init__.py", line 36, in autodetect
    from google.appengine.api import memcache
ModuleNotFoundError: No module named 'google'

During handling of the above exception, another exception occurred:

Traceback (most recent call last):
  File "/usr/local/lib/python3.6/site-packages/google_api_python_client-1.6.2-py3.6.egg/googleapiclient/discovery_cache/file_cache.py", line 33, in <module>
    from oauth2client.contrib.locked_file import LockedFile
ModuleNotFoundError: No module named 'oauth2client.contrib.locked_file'

During handling of the above exception, another exception occurred:

Traceback (most recent call last):
  File "/usr/local/lib/python3.6/site-packages/google_api_python_client-1.6.2-py3.6.egg/googleapiclient/discovery_cache/file_cache.py", line 37, in <module>
    from oauth2client.locked_file import LockedFile
ModuleNotFoundError: No module named 'oauth2client.locked_file'

During handling of the above exception, another exception occurred:

Traceback (most recent call last):
  File "/usr/local/lib/python3.6/site-packages/google_api_python_client-1.6.2-py3.6.egg/googleapiclient/discovery_cache/__init__.py", line 41, in autodetect
    from . import file_cache
  File "/usr/local/lib/python3.6/site-packages/google_api_python_client-1.6.2-py3.6.egg/googleapiclient/discovery_cache/file_cache.py", line 41, in <module>
    'file_cache is unavailable when using oauth2client >= 4.0.0')
ImportError: file_cache is unavailable when using oauth2client >= 4.0.0
2017-05-08 00:20:48,110 URL being requested: GET https://www.googleapis.com/discovery/v1/apis/calendar/v3/rest
2017-05-08 00:20:48,293 URL being requested: GET https://www.googleapis.com/calendar/v3/calendars/primary/events?timeMin=2017-05-08T00%3A20%3A48.264468Z&maxResults=10&singleEvents=true&orderBy=startTime&alt=json
2017-05-08 00:20:48,391 Updating 0.152.255.115.20's event list
2017-05-08 00:20:48,391 0.152.255.115.20's event has been collected
2017-05-08 00:30:16,158 0.152.255.115.20 has logged in
2017-05-08 00:30:16,177 file_cache is unavailable when using oauth2client >= 4.0.0
Traceback (most recent call last):
  File "/usr/local/lib/python3.6/site-packages/google_api_python_client-1.6.2-py3.6.egg/googleapiclient/discovery_cache/__init__.py", line 36, in autodetect
    from google.appengine.api import memcache
ModuleNotFoundError: No module named 'google'

During handling of the above exception, another exception occurred:

Traceback (most recent call last):
  File "/usr/local/lib/python3.6/site-packages/google_api_python_client-1.6.2-py3.6.egg/googleapiclient/discovery_cache/file_cache.py", line 33, in <module>
    from oauth2client.contrib.locked_file import LockedFile
ModuleNotFoundError: No module named 'oauth2client.contrib.locked_file'

During handling of the above exception, another exception occurred:

Traceback (most recent call last):
  File "/usr/local/lib/python3.6/site-packages/google_api_python_client-1.6.2-py3.6.egg/googleapiclient/discovery_cache/file_cache.py", line 37, in <module>
    from oauth2client.locked_file import LockedFile
ModuleNotFoundError: No module named 'oauth2client.locked_file'

During handling of the above exception, another exception occurred:

Traceback (most recent call last):
  File "/usr/local/lib/python3.6/site-packages/google_api_python_client-1.6.2-py3.6.egg/googleapiclient/discovery_cache/__init__.py", line 41, in autodetect
    from . import file_cache
  File "/usr/local/lib/python3.6/site-packages/google_api_python_client-1.6.2-py3.6.egg/googleapiclient/discovery_cache/file_cache.py", line 41, in <module>
    'file_cache is unavailable when using oauth2client >= 4.0.0')
ImportError: file_cache is unavailable when using oauth2client >= 4.0.0
2017-05-08 00:30:16,179 URL being requested: GET https://www.googleapis.com/discovery/v1/apis/calendar/v3/rest
2017-05-08 00:30:16,344 URL being requested: GET https://www.googleapis.com/calendar/v3/calendars/primary/events?timeMin=2017-05-08T00%3A30%3A16.314731Z&maxResults=10&singleEvents=true&orderBy=startTime&alt=json
2017-05-08 00:30:16,384 Refreshing due to a 401 (attempt 1/2)
2017-05-08 00:30:16,385 Refreshing access_token
2017-05-08 00:30:16,652 0.152.255.115.20's event has been collected
2017-05-08 00:30:27,170 Notify 0.152.255.115.20 event in 5 min
2017-05-08 00:32:33,302 file_cache is unavailable when using oauth2client >= 4.0.0
Traceback (most recent call last):
  File "/usr/local/lib/python3.6/site-packages/google_api_python_client-1.6.2-py3.6.egg/googleapiclient/discovery_cache/__init__.py", line 36, in autodetect
    from google.appengine.api import memcache
ModuleNotFoundError: No module named 'google'

During handling of the above exception, another exception occurred:

Traceback (most recent call last):
  File "/usr/local/lib/python3.6/site-packages/google_api_python_client-1.6.2-py3.6.egg/googleapiclient/discovery_cache/file_cache.py", line 33, in <module>
    from oauth2client.contrib.locked_file import LockedFile
ModuleNotFoundError: No module named 'oauth2client.contrib.locked_file'

During handling of the above exception, another exception occurred:

Traceback (most recent call last):
  File "/usr/local/lib/python3.6/site-packages/google_api_python_client-1.6.2-py3.6.egg/googleapiclient/discovery_cache/file_cache.py", line 37, in <module>
    from oauth2client.locked_file import LockedFile
ModuleNotFoundError: No module named 'oauth2client.locked_file'

During handling of the above exception, another exception occurred:

Traceback (most recent call last):
  File "/usr/local/lib/python3.6/site-packages/google_api_python_client-1.6.2-py3.6.egg/googleapiclient/discovery_cache/__init__.py", line 41, in autodetect
    from . import file_cache
  File "/usr/local/lib/python3.6/site-packages/google_api_python_client-1.6.2-py3.6.egg/googleapiclient/discovery_cache/file_cache.py", line 41, in <module>
    'file_cache is unavailable when using oauth2client >= 4.0.0')
ImportError: file_cache is unavailable when using oauth2client >= 4.0.0
2017-05-08 00:32:33,305 URL being requested: GET https://www.googleapis.com/discovery/v1/apis/calendar/v3/rest
2017-05-08 00:32:33,498 URL being requested: GET https://www.googleapis.com/calendar/v3/calendars/primary/events?timeMin=2017-05-08T00%3A32%3A33.459051Z&maxResults=10&singleEvents=true&orderBy=startTime&alt=json
2017-05-08 00:32:33,609 Updating 0.152.255.115.20's event list
2017-05-08 00:32:33,610 0.152.255.115.20's event has been collected
2017-05-08 00:32:44,132 Notify 0.152.255.115.20 event in 5 min
2017-05-07 20:50:16,462 0.152.255.115.20 has logged in
2017-05-07 20:50:16,484 file_cache is unavailable when using oauth2client >= 4.0.0
Traceback (most recent call last):
  File "/usr/local/lib/python3.6/site-packages/google_api_python_client-1.6.2-py3.6.egg/googleapiclient/discovery_cache/__init__.py", line 36, in autodetect
    from google.appengine.api import memcache
ModuleNotFoundError: No module named 'google'

During handling of the above exception, another exception occurred:

Traceback (most recent call last):
  File "/usr/local/lib/python3.6/site-packages/google_api_python_client-1.6.2-py3.6.egg/googleapiclient/discovery_cache/file_cache.py", line 33, in <module>
    from oauth2client.contrib.locked_file import LockedFile
ModuleNotFoundError: No module named 'oauth2client.contrib.locked_file'

During handling of the above exception, another exception occurred:

Traceback (most recent call last):
  File "/usr/local/lib/python3.6/site-packages/google_api_python_client-1.6.2-py3.6.egg/googleapiclient/discovery_cache/file_cache.py", line 37, in <module>
    from oauth2client.locked_file import LockedFile
ModuleNotFoundError: No module named 'oauth2client.locked_file'

During handling of the above exception, another exception occurred:

Traceback (most recent call last):
  File "/usr/local/lib/python3.6/site-packages/google_api_python_client-1.6.2-py3.6.egg/googleapiclient/discovery_cache/__init__.py", line 41, in autodetect
    from . import file_cache
  File "/usr/local/lib/python3.6/site-packages/google_api_python_client-1.6.2-py3.6.egg/googleapiclient/discovery_cache/file_cache.py", line 41, in <module>
    'file_cache is unavailable when using oauth2client >= 4.0.0')
ImportError: file_cache is unavailable when using oauth2client >= 4.0.0
2017-05-07 20:50:16,486 URL being requested: GET https://www.googleapis.com/discovery/v1/apis/calendar/v3/rest
2017-05-07 20:50:16,650 URL being requested: GET https://www.googleapis.com/calendar/v3/calendars/primary/events?timeMin=2017-05-08T00%3A50%3A16.621827Z&maxResults=10&singleEvents=true&orderBy=startTime&alt=json
2017-05-07 20:50:16,689 Refreshing due to a 401 (attempt 1/2)
2017-05-07 20:50:16,690 Refreshing access_token
2017-05-07 20:52:15,563 149.54.23.70.242 tries to log in but has not registered yet
2017-05-07 20:52:19,327 0.152.255.115.20 has logged in
2017-05-07 20:52:19,346 file_cache is unavailable when using oauth2client >= 4.0.0
Traceback (most recent call last):
  File "/usr/local/lib/python3.6/site-packages/google_api_python_client-1.6.2-py3.6.egg/googleapiclient/discovery_cache/__init__.py", line 36, in autodetect
    from google.appengine.api import memcache
ModuleNotFoundError: No module named 'google'

During handling of the above exception, another exception occurred:

Traceback (most recent call last):
  File "/usr/local/lib/python3.6/site-packages/google_api_python_client-1.6.2-py3.6.egg/googleapiclient/discovery_cache/file_cache.py", line 33, in <module>
    from oauth2client.contrib.locked_file import LockedFile
ModuleNotFoundError: No module named 'oauth2client.contrib.locked_file'

During handling of the above exception, another exception occurred:

Traceback (most recent call last):
  File "/usr/local/lib/python3.6/site-packages/google_api_python_client-1.6.2-py3.6.egg/googleapiclient/discovery_cache/file_cache.py", line 37, in <module>
    from oauth2client.locked_file import LockedFile
ModuleNotFoundError: No module named 'oauth2client.locked_file'

During handling of the above exception, another exception occurred:

Traceback (most recent call last):
  File "/usr/local/lib/python3.6/site-packages/google_api_python_client-1.6.2-py3.6.egg/googleapiclient/discovery_cache/__init__.py", line 41, in autodetect
    from . import file_cache
  File "/usr/local/lib/python3.6/site-packages/google_api_python_client-1.6.2-py3.6.egg/googleapiclient/discovery_cache/file_cache.py", line 41, in <module>
    'file_cache is unavailable when using oauth2client >= 4.0.0')
ImportError: file_cache is unavailable when using oauth2client >= 4.0.0
2017-05-07 20:52:19,348 URL being requested: GET https://www.googleapis.com/discovery/v1/apis/calendar/v3/rest
2017-05-07 20:52:19,520 URL being requested: GET https://www.googleapis.com/calendar/v3/calendars/primary/events?timeMin=2017-05-08T00%3A52%3A19.491307Z&maxResults=10&singleEvents=true&orderBy=startTime&alt=json
2017-05-07 20:52:19,578 Refreshing due to a 401 (attempt 1/2)
2017-05-07 20:52:19,579 Refreshing access_token
2017-05-07 20:53:03,681 0.152.255.115.20 has logged in
2017-05-07 20:53:03,693 file_cache is unavailable when using oauth2client >= 4.0.0
Traceback (most recent call last):
  File "/usr/local/lib/python3.6/site-packages/google_api_python_client-1.6.2-py3.6.egg/googleapiclient/discovery_cache/__init__.py", line 36, in autodetect
    from google.appengine.api import memcache
ModuleNotFoundError: No module named 'google'

During handling of the above exception, another exception occurred:

Traceback (most recent call last):
  File "/usr/local/lib/python3.6/site-packages/google_api_python_client-1.6.2-py3.6.egg/googleapiclient/discovery_cache/file_cache.py", line 33, in <module>
    from oauth2client.contrib.locked_file import LockedFile
ModuleNotFoundError: No module named 'oauth2client.contrib.locked_file'

During handling of the above exception, another exception occurred:

Traceback (most recent call last):
  File "/usr/local/lib/python3.6/site-packages/google_api_python_client-1.6.2-py3.6.egg/googleapiclient/discovery_cache/file_cache.py", line 37, in <module>
    from oauth2client.locked_file import LockedFile
ModuleNotFoundError: No module named 'oauth2client.locked_file'

During handling of the above exception, another exception occurred:

Traceback (most recent call last):
  File "/usr/local/lib/python3.6/site-packages/google_api_python_client-1.6.2-py3.6.egg/googleapiclient/discovery_cache/__init__.py", line 41, in autodetect
    from . import file_cache
  File "/usr/local/lib/python3.6/site-packages/google_api_python_client-1.6.2-py3.6.egg/googleapiclient/discovery_cache/file_cache.py", line 41, in <module>
    'file_cache is unavailable when using oauth2client >= 4.0.0')
ImportError: file_cache is unavailable when using oauth2client >= 4.0.0
2017-05-07 20:53:03,694 URL being requested: GET https://www.googleapis.com/discovery/v1/apis/calendar/v3/rest
2017-05-07 20:53:03,845 URL being requested: GET https://www.googleapis.com/calendar/v3/calendars/primary/events?timeMin=2017-05-08T00%3A53%3A03.815883Z&maxResults=10&singleEvents=true&orderBy=startTime&alt=json
2017-05-07 20:53:03,919 Refreshing due to a 401 (attempt 1/2)
2017-05-07 20:53:03,920 Refreshing access_token
2017-05-07 20:53:13,767 0.152.255.115.20 has logged in
2017-05-07 20:53:13,779 file_cache is unavailable when using oauth2client >= 4.0.0
Traceback (most recent call last):
  File "/usr/local/lib/python3.6/site-packages/google_api_python_client-1.6.2-py3.6.egg/googleapiclient/discovery_cache/__init__.py", line 36, in autodetect
    from google.appengine.api import memcache
ModuleNotFoundError: No module named 'google'

During handling of the above exception, another exception occurred:

Traceback (most recent call last):
  File "/usr/local/lib/python3.6/site-packages/google_api_python_client-1.6.2-py3.6.egg/googleapiclient/discovery_cache/file_cache.py", line 33, in <module>
    from oauth2client.contrib.locked_file import LockedFile
ModuleNotFoundError: No module named 'oauth2client.contrib.locked_file'

During handling of the above exception, another exception occurred:

Traceback (most recent call last):
  File "/usr/local/lib/python3.6/site-packages/google_api_python_client-1.6.2-py3.6.egg/googleapiclient/discovery_cache/file_cache.py", line 37, in <module>
    from oauth2client.locked_file import LockedFile
ModuleNotFoundError: No module named 'oauth2client.locked_file'

During handling of the above exception, another exception occurred:

Traceback (most recent call last):
  File "/usr/local/lib/python3.6/site-packages/google_api_python_client-1.6.2-py3.6.egg/googleapiclient/discovery_cache/__init__.py", line 41, in autodetect
    from . import file_cache
  File "/usr/local/lib/python3.6/site-packages/google_api_python_client-1.6.2-py3.6.egg/googleapiclient/discovery_cache/file_cache.py", line 41, in <module>
    'file_cache is unavailable when using oauth2client >= 4.0.0')
ImportError: file_cache is unavailable when using oauth2client >= 4.0.0
2017-05-07 20:53:13,781 URL being requested: GET https://www.googleapis.com/discovery/v1/apis/calendar/v3/rest
2017-05-07 20:53:13,937 URL being requested: GET https://www.googleapis.com/calendar/v3/calendars/primary/events?timeMin=2017-05-08T00%3A53%3A13.907439Z&maxResults=10&singleEvents=true&orderBy=startTime&alt=json
2017-05-07 20:53:13,978 Refreshing due to a 401 (attempt 1/2)
2017-05-07 20:53:13,978 Refreshing access_token
2017-05-07 20:53:17,491 0.152.255.115.20 has logged in
2017-05-07 20:53:17,503 file_cache is unavailable when using oauth2client >= 4.0.0
Traceback (most recent call last):
  File "/usr/local/lib/python3.6/site-packages/google_api_python_client-1.6.2-py3.6.egg/googleapiclient/discovery_cache/__init__.py", line 36, in autodetect
    from google.appengine.api import memcache
ModuleNotFoundError: No module named 'google'

During handling of the above exception, another exception occurred:

Traceback (most recent call last):
  File "/usr/local/lib/python3.6/site-packages/google_api_python_client-1.6.2-py3.6.egg/googleapiclient/discovery_cache/file_cache.py", line 33, in <module>
    from oauth2client.contrib.locked_file import LockedFile
ModuleNotFoundError: No module named 'oauth2client.contrib.locked_file'

During handling of the above exception, another exception occurred:

Traceback (most recent call last):
  File "/usr/local/lib/python3.6/site-packages/google_api_python_client-1.6.2-py3.6.egg/googleapiclient/discovery_cache/file_cache.py", line 37, in <module>
    from oauth2client.locked_file import LockedFile
ModuleNotFoundError: No module named 'oauth2client.locked_file'

During handling of the above exception, another exception occurred:

Traceback (most recent call last):
  File "/usr/local/lib/python3.6/site-packages/google_api_python_client-1.6.2-py3.6.egg/googleapiclient/discovery_cache/__init__.py", line 41, in autodetect
    from . import file_cache
  File "/usr/local/lib/python3.6/site-packages/google_api_python_client-1.6.2-py3.6.egg/googleapiclient/discovery_cache/file_cache.py", line 41, in <module>
    'file_cache is unavailable when using oauth2client >= 4.0.0')
ImportError: file_cache is unavailable when using oauth2client >= 4.0.0
2017-05-07 20:53:17,504 URL being requested: GET https://www.googleapis.com/discovery/v1/apis/calendar/v3/rest
2017-05-07 20:53:17,658 URL being requested: GET https://www.googleapis.com/calendar/v3/calendars/primary/events?timeMin=2017-05-08T00%3A53%3A17.628294Z&maxResults=10&singleEvents=true&orderBy=startTime&alt=json
2017-05-07 20:53:17,698 Refreshing due to a 401 (attempt 1/2)
2017-05-07 20:53:17,698 Refreshing access_token
2017-05-07 20:53:21,231 0.152.255.115.20 has logged in
2017-05-07 20:53:21,244 file_cache is unavailable when using oauth2client >= 4.0.0
Traceback (most recent call last):
  File "/usr/local/lib/python3.6/site-packages/google_api_python_client-1.6.2-py3.6.egg/googleapiclient/discovery_cache/__init__.py", line 36, in autodetect
    from google.appengine.api import memcache
ModuleNotFoundError: No module named 'google'

During handling of the above exception, another exception occurred:

Traceback (most recent call last):
  File "/usr/local/lib/python3.6/site-packages/google_api_python_client-1.6.2-py3.6.egg/googleapiclient/discovery_cache/file_cache.py", line 33, in <module>
    from oauth2client.contrib.locked_file import LockedFile
ModuleNotFoundError: No module named 'oauth2client.contrib.locked_file'

During handling of the above exception, another exception occurred:

Traceback (most recent call last):
  File "/usr/local/lib/python3.6/site-packages/google_api_python_client-1.6.2-py3.6.egg/googleapiclient/discovery_cache/file_cache.py", line 37, in <module>
    from oauth2client.locked_file import LockedFile
ModuleNotFoundError: No module named 'oauth2client.locked_file'

During handling of the above exception, another exception occurred:

Traceback (most recent call last):
  File "/usr/local/lib/python3.6/site-packages/google_api_python_client-1.6.2-py3.6.egg/googleapiclient/discovery_cache/__init__.py", line 41, in autodetect
    from . import file_cache
  File "/usr/local/lib/python3.6/site-packages/google_api_python_client-1.6.2-py3.6.egg/googleapiclient/discovery_cache/file_cache.py", line 41, in <module>
    'file_cache is unavailable when using oauth2client >= 4.0.0')
ImportError: file_cache is unavailable when using oauth2client >= 4.0.0
2017-05-07 20:53:21,245 URL being requested: GET https://www.googleapis.com/discovery/v1/apis/calendar/v3/rest
2017-05-07 20:53:21,638 URL being requested: GET https://www.googleapis.com/calendar/v3/calendars/primary/events?timeMin=2017-05-08T00%3A53%3A21.608664Z&maxResults=10&singleEvents=true&orderBy=startTime&alt=json
2017-05-07 20:53:21,682 Refreshing due to a 401 (attempt 1/2)
2017-05-07 20:53:21,683 Refreshing access_token
2017-05-07 20:53:25,221 0.152.255.115.20 has logged in
2017-05-07 20:53:25,233 file_cache is unavailable when using oauth2client >= 4.0.0
Traceback (most recent call last):
  File "/usr/local/lib/python3.6/site-packages/google_api_python_client-1.6.2-py3.6.egg/googleapiclient/discovery_cache/__init__.py", line 36, in autodetect
    from google.appengine.api import memcache
ModuleNotFoundError: No module named 'google'

During handling of the above exception, another exception occurred:

Traceback (most recent call last):
  File "/usr/local/lib/python3.6/site-packages/google_api_python_client-1.6.2-py3.6.egg/googleapiclient/discovery_cache/file_cache.py", line 33, in <module>
    from oauth2client.contrib.locked_file import LockedFile
ModuleNotFoundError: No module named 'oauth2client.contrib.locked_file'

During handling of the above exception, another exception occurred:

Traceback (most recent call last):
  File "/usr/local/lib/python3.6/site-packages/google_api_python_client-1.6.2-py3.6.egg/googleapiclient/discovery_cache/file_cache.py", line 37, in <module>
    from oauth2client.locked_file import LockedFile
ModuleNotFoundError: No module named 'oauth2client.locked_file'

During handling of the above exception, another exception occurred:

Traceback (most recent call last):
  File "/usr/local/lib/python3.6/site-packages/google_api_python_client-1.6.2-py3.6.egg/googleapiclient/discovery_cache/__init__.py", line 41, in autodetect
    from . import file_cache
  File "/usr/local/lib/python3.6/site-packages/google_api_python_client-1.6.2-py3.6.egg/googleapiclient/discovery_cache/file_cache.py", line 41, in <module>
    'file_cache is unavailable when using oauth2client >= 4.0.0')
ImportError: file_cache is unavailable when using oauth2client >= 4.0.0
2017-05-07 20:53:25,235 URL being requested: GET https://www.googleapis.com/discovery/v1/apis/calendar/v3/rest
2017-05-07 20:53:25,443 URL being requested: GET https://www.googleapis.com/calendar/v3/calendars/primary/events?timeMin=2017-05-08T00%3A53%3A25.360070Z&maxResults=10&singleEvents=true&orderBy=startTime&alt=json
2017-05-07 20:53:25,486 Refreshing due to a 401 (attempt 1/2)
2017-05-07 20:53:25,487 Refreshing access_token
2017-05-07 20:53:47,544 0.152.255.115.20 has logged in
2017-05-07 20:53:47,556 file_cache is unavailable when using oauth2client >= 4.0.0
Traceback (most recent call last):
  File "/usr/local/lib/python3.6/site-packages/google_api_python_client-1.6.2-py3.6.egg/googleapiclient/discovery_cache/__init__.py", line 36, in autodetect
    from google.appengine.api import memcache
ModuleNotFoundError: No module named 'google'

During handling of the above exception, another exception occurred:

Traceback (most recent call last):
  File "/usr/local/lib/python3.6/site-packages/google_api_python_client-1.6.2-py3.6.egg/googleapiclient/discovery_cache/file_cache.py", line 33, in <module>
    from oauth2client.contrib.locked_file import LockedFile
ModuleNotFoundError: No module named 'oauth2client.contrib.locked_file'

During handling of the above exception, another exception occurred:

Traceback (most recent call last):
  File "/usr/local/lib/python3.6/site-packages/google_api_python_client-1.6.2-py3.6.egg/googleapiclient/discovery_cache/file_cache.py", line 37, in <module>
    from oauth2client.locked_file import LockedFile
ModuleNotFoundError: No module named 'oauth2client.locked_file'

During handling of the above exception, another exception occurred:

Traceback (most recent call last):
  File "/usr/local/lib/python3.6/site-packages/google_api_python_client-1.6.2-py3.6.egg/googleapiclient/discovery_cache/__init__.py", line 41, in autodetect
    from . import file_cache
  File "/usr/local/lib/python3.6/site-packages/google_api_python_client-1.6.2-py3.6.egg/googleapiclient/discovery_cache/file_cache.py", line 41, in <module>
    'file_cache is unavailable when using oauth2client >= 4.0.0')
ImportError: file_cache is unavailable when using oauth2client >= 4.0.0
2017-05-07 20:53:47,558 URL being requested: GET https://www.googleapis.com/discovery/v1/apis/calendar/v3/rest
2017-05-07 20:53:47,711 URL being requested: GET https://www.googleapis.com/calendar/v3/calendars/primary/events?timeMin=2017-05-08T00%3A53%3A47.681940Z&maxResults=10&singleEvents=true&orderBy=startTime&alt=json
2017-05-07 20:53:47,756 Refreshing due to a 401 (attempt 1/2)
2017-05-07 20:53:47,757 Refreshing access_token
2017-05-07 20:54:50,953 0.152.255.115.20 has logged in
2017-05-07 20:54:50,971 file_cache is unavailable when using oauth2client >= 4.0.0
Traceback (most recent call last):
  File "/usr/local/lib/python3.6/site-packages/google_api_python_client-1.6.2-py3.6.egg/googleapiclient/discovery_cache/__init__.py", line 36, in autodetect
    from google.appengine.api import memcache
ModuleNotFoundError: No module named 'google'

During handling of the above exception, another exception occurred:

Traceback (most recent call last):
  File "/usr/local/lib/python3.6/site-packages/google_api_python_client-1.6.2-py3.6.egg/googleapiclient/discovery_cache/file_cache.py", line 33, in <module>
    from oauth2client.contrib.locked_file import LockedFile
ModuleNotFoundError: No module named 'oauth2client.contrib.locked_file'

During handling of the above exception, another exception occurred:

Traceback (most recent call last):
  File "/usr/local/lib/python3.6/site-packages/google_api_python_client-1.6.2-py3.6.egg/googleapiclient/discovery_cache/file_cache.py", line 37, in <module>
    from oauth2client.locked_file import LockedFile
ModuleNotFoundError: No module named 'oauth2client.locked_file'

During handling of the above exception, another exception occurred:

Traceback (most recent call last):
  File "/usr/local/lib/python3.6/site-packages/google_api_python_client-1.6.2-py3.6.egg/googleapiclient/discovery_cache/__init__.py", line 41, in autodetect
    from . import file_cache
  File "/usr/local/lib/python3.6/site-packages/google_api_python_client-1.6.2-py3.6.egg/googleapiclient/discovery_cache/file_cache.py", line 41, in <module>
    'file_cache is unavailable when using oauth2client >= 4.0.0')
ImportError: file_cache is unavailable when using oauth2client >= 4.0.0
2017-05-07 20:54:50,974 URL being requested: GET https://www.googleapis.com/discovery/v1/apis/calendar/v3/rest
2017-05-07 20:54:51,140 URL being requested: GET https://www.googleapis.com/calendar/v3/calendars/primary/events?timeMin=2017-05-08T00%3A54%3A51.111301Z&maxResults=10&singleEvents=true&orderBy=startTime&alt=json
2017-05-07 20:54:51,182 Refreshing due to a 401 (attempt 1/2)
2017-05-07 20:54:51,183 Refreshing access_token
2017-05-07 20:59:23,572 149.54.23.70.242 tries to log in but has not registered yet
2017-05-07 20:59:26,690 0.152.255.115.20 has logged in
2017-05-07 20:59:26,709 file_cache is unavailable when using oauth2client >= 4.0.0
Traceback (most recent call last):
  File "/usr/local/lib/python3.6/site-packages/google_api_python_client-1.6.2-py3.6.egg/googleapiclient/discovery_cache/__init__.py", line 36, in autodetect
    from google.appengine.api import memcache
ModuleNotFoundError: No module named 'google'

During handling of the above exception, another exception occurred:

Traceback (most recent call last):
  File "/usr/local/lib/python3.6/site-packages/google_api_python_client-1.6.2-py3.6.egg/googleapiclient/discovery_cache/file_cache.py", line 33, in <module>
    from oauth2client.contrib.locked_file import LockedFile
ModuleNotFoundError: No module named 'oauth2client.contrib.locked_file'

During handling of the above exception, another exception occurred:

Traceback (most recent call last):
  File "/usr/local/lib/python3.6/site-packages/google_api_python_client-1.6.2-py3.6.egg/googleapiclient/discovery_cache/file_cache.py", line 37, in <module>
    from oauth2client.locked_file import LockedFile
ModuleNotFoundError: No module named 'oauth2client.locked_file'

During handling of the above exception, another exception occurred:

Traceback (most recent call last):
  File "/usr/local/lib/python3.6/site-packages/google_api_python_client-1.6.2-py3.6.egg/googleapiclient/discovery_cache/__init__.py", line 41, in autodetect
    from . import file_cache
  File "/usr/local/lib/python3.6/site-packages/google_api_python_client-1.6.2-py3.6.egg/googleapiclient/discovery_cache/file_cache.py", line 41, in <module>
    'file_cache is unavailable when using oauth2client >= 4.0.0')
ImportError: file_cache is unavailable when using oauth2client >= 4.0.0
2017-05-07 20:59:26,712 URL being requested: GET https://www.googleapis.com/discovery/v1/apis/calendar/v3/rest
2017-05-07 20:59:26,871 URL being requested: GET https://www.googleapis.com/calendar/v3/calendars/primary/events?timeMin=2017-05-08T00%3A59%3A26.839753Z&maxResults=10&singleEvents=true&orderBy=startTime&alt=json
2017-05-07 20:59:26,914 Refreshing due to a 401 (attempt 1/2)
2017-05-07 20:59:26,915 Refreshing access_token
2017-05-07 21:02:47,720 0.152.255.115.20 has logged in
2017-05-07 21:02:47,738 file_cache is unavailable when using oauth2client >= 4.0.0
Traceback (most recent call last):
  File "/usr/local/lib/python3.6/site-packages/google_api_python_client-1.6.2-py3.6.egg/googleapiclient/discovery_cache/__init__.py", line 36, in autodetect
    from google.appengine.api import memcache
ModuleNotFoundError: No module named 'google'

During handling of the above exception, another exception occurred:

Traceback (most recent call last):
  File "/usr/local/lib/python3.6/site-packages/google_api_python_client-1.6.2-py3.6.egg/googleapiclient/discovery_cache/file_cache.py", line 33, in <module>
    from oauth2client.contrib.locked_file import LockedFile
ModuleNotFoundError: No module named 'oauth2client.contrib.locked_file'

During handling of the above exception, another exception occurred:

Traceback (most recent call last):
  File "/usr/local/lib/python3.6/site-packages/google_api_python_client-1.6.2-py3.6.egg/googleapiclient/discovery_cache/file_cache.py", line 37, in <module>
    from oauth2client.locked_file import LockedFile
ModuleNotFoundError: No module named 'oauth2client.locked_file'

During handling of the above exception, another exception occurred:

Traceback (most recent call last):
  File "/usr/local/lib/python3.6/site-packages/google_api_python_client-1.6.2-py3.6.egg/googleapiclient/discovery_cache/__init__.py", line 41, in autodetect
    from . import file_cache
  File "/usr/local/lib/python3.6/site-packages/google_api_python_client-1.6.2-py3.6.egg/googleapiclient/discovery_cache/file_cache.py", line 41, in <module>
    'file_cache is unavailable when using oauth2client >= 4.0.0')
ImportError: file_cache is unavailable when using oauth2client >= 4.0.0
2017-05-07 21:02:47,741 URL being requested: GET https://www.googleapis.com/discovery/v1/apis/calendar/v3/rest
2017-05-07 21:02:47,921 URL being requested: GET https://www.googleapis.com/calendar/v3/calendars/primary/events?timeMin=2017-05-08T01%3A02%3A47.882850Z&maxResults=10&singleEvents=true&orderBy=startTime&alt=json
2017-05-07 21:02:47,964 Refreshing due to a 401 (attempt 1/2)
2017-05-07 21:02:47,966 Refreshing access_token
2017-05-07 21:03:06,990 0.152.255.115.20 has logged in
2017-05-07 21:03:07,002 file_cache is unavailable when using oauth2client >= 4.0.0
Traceback (most recent call last):
  File "/usr/local/lib/python3.6/site-packages/google_api_python_client-1.6.2-py3.6.egg/googleapiclient/discovery_cache/__init__.py", line 36, in autodetect
    from google.appengine.api import memcache
ModuleNotFoundError: No module named 'google'

During handling of the above exception, another exception occurred:

Traceback (most recent call last):
  File "/usr/local/lib/python3.6/site-packages/google_api_python_client-1.6.2-py3.6.egg/googleapiclient/discovery_cache/file_cache.py", line 33, in <module>
    from oauth2client.contrib.locked_file import LockedFile
ModuleNotFoundError: No module named 'oauth2client.contrib.locked_file'

During handling of the above exception, another exception occurred:

Traceback (most recent call last):
  File "/usr/local/lib/python3.6/site-packages/google_api_python_client-1.6.2-py3.6.egg/googleapiclient/discovery_cache/file_cache.py", line 37, in <module>
    from oauth2client.locked_file import LockedFile
ModuleNotFoundError: No module named 'oauth2client.locked_file'

During handling of the above exception, another exception occurred:

Traceback (most recent call last):
  File "/usr/local/lib/python3.6/site-packages/google_api_python_client-1.6.2-py3.6.egg/googleapiclient/discovery_cache/__init__.py", line 41, in autodetect
    from . import file_cache
  File "/usr/local/lib/python3.6/site-packages/google_api_python_client-1.6.2-py3.6.egg/googleapiclient/discovery_cache/file_cache.py", line 41, in <module>
    'file_cache is unavailable when using oauth2client >= 4.0.0')
ImportError: file_cache is unavailable when using oauth2client >= 4.0.0
2017-05-07 21:03:07,003 URL being requested: GET https://www.googleapis.com/discovery/v1/apis/calendar/v3/rest
2017-05-07 21:03:07,212 URL being requested: GET https://www.googleapis.com/calendar/v3/calendars/primary/events?timeMin=2017-05-08T01%3A03%3A07.175855Z&maxResults=10&singleEvents=true&orderBy=startTime&alt=json
2017-05-07 21:03:07,268 Refreshing due to a 401 (attempt 1/2)
2017-05-07 21:03:07,268 Refreshing access_token
2017-05-07 21:04:45,642 0.152.255.115.20 has logged in
2017-05-07 21:04:45,661 file_cache is unavailable when using oauth2client >= 4.0.0
Traceback (most recent call last):
  File "/usr/local/lib/python3.6/site-packages/google_api_python_client-1.6.2-py3.6.egg/googleapiclient/discovery_cache/__init__.py", line 36, in autodetect
    from google.appengine.api import memcache
ModuleNotFoundError: No module named 'google'

During handling of the above exception, another exception occurred:

Traceback (most recent call last):
  File "/usr/local/lib/python3.6/site-packages/google_api_python_client-1.6.2-py3.6.egg/googleapiclient/discovery_cache/file_cache.py", line 33, in <module>
    from oauth2client.contrib.locked_file import LockedFile
ModuleNotFoundError: No module named 'oauth2client.contrib.locked_file'

During handling of the above exception, another exception occurred:

Traceback (most recent call last):
  File "/usr/local/lib/python3.6/site-packages/google_api_python_client-1.6.2-py3.6.egg/googleapiclient/discovery_cache/file_cache.py", line 37, in <module>
    from oauth2client.locked_file import LockedFile
ModuleNotFoundError: No module named 'oauth2client.locked_file'

During handling of the above exception, another exception occurred:

Traceback (most recent call last):
  File "/usr/local/lib/python3.6/site-packages/google_api_python_client-1.6.2-py3.6.egg/googleapiclient/discovery_cache/__init__.py", line 41, in autodetect
    from . import file_cache
  File "/usr/local/lib/python3.6/site-packages/google_api_python_client-1.6.2-py3.6.egg/googleapiclient/discovery_cache/file_cache.py", line 41, in <module>
    'file_cache is unavailable when using oauth2client >= 4.0.0')
ImportError: file_cache is unavailable when using oauth2client >= 4.0.0
2017-05-07 21:04:45,663 URL being requested: GET https://www.googleapis.com/discovery/v1/apis/calendar/v3/rest
2017-05-07 21:04:45,829 URL being requested: GET https://www.googleapis.com/calendar/v3/calendars/primary/events?timeMin=2017-05-08T01%3A04%3A45.798268Z&maxResults=10&singleEvents=true&orderBy=startTime&alt=json
2017-05-07 21:04:45,892 Refreshing due to a 401 (attempt 1/2)
2017-05-07 21:04:45,892 Refreshing access_token
2017-05-07 21:08:21,953 0.152.255.115.20 has logged in
2017-05-07 21:08:21,972 file_cache is unavailable when using oauth2client >= 4.0.0
Traceback (most recent call last):
  File "/usr/local/lib/python3.6/site-packages/google_api_python_client-1.6.2-py3.6.egg/googleapiclient/discovery_cache/__init__.py", line 36, in autodetect
    from google.appengine.api import memcache
ModuleNotFoundError: No module named 'google'

During handling of the above exception, another exception occurred:

Traceback (most recent call last):
  File "/usr/local/lib/python3.6/site-packages/google_api_python_client-1.6.2-py3.6.egg/googleapiclient/discovery_cache/file_cache.py", line 33, in <module>
    from oauth2client.contrib.locked_file import LockedFile
ModuleNotFoundError: No module named 'oauth2client.contrib.locked_file'

During handling of the above exception, another exception occurred:

Traceback (most recent call last):
  File "/usr/local/lib/python3.6/site-packages/google_api_python_client-1.6.2-py3.6.egg/googleapiclient/discovery_cache/file_cache.py", line 37, in <module>
    from oauth2client.locked_file import LockedFile
ModuleNotFoundError: No module named 'oauth2client.locked_file'

During handling of the above exception, another exception occurred:

Traceback (most recent call last):
  File "/usr/local/lib/python3.6/site-packages/google_api_python_client-1.6.2-py3.6.egg/googleapiclient/discovery_cache/__init__.py", line 41, in autodetect
    from . import file_cache
  File "/usr/local/lib/python3.6/site-packages/google_api_python_client-1.6.2-py3.6.egg/googleapiclient/discovery_cache/file_cache.py", line 41, in <module>
    'file_cache is unavailable when using oauth2client >= 4.0.0')
ImportError: file_cache is unavailable when using oauth2client >= 4.0.0
2017-05-07 21:08:21,975 URL being requested: GET https://www.googleapis.com/discovery/v1/apis/calendar/v3/rest
2017-05-07 21:08:22,142 URL being requested: GET https://www.googleapis.com/calendar/v3/calendars/primary/events?timeMin=2017-05-08T01%3A08%3A22.110569Z&maxResults=10&singleEvents=true&orderBy=startTime&alt=json
2017-05-07 21:08:22,185 Refreshing due to a 401 (attempt 1/2)
2017-05-07 21:08:22,186 Refreshing access_token
2017-05-07 21:09:13,753 0.152.255.115.20 has logged in
2017-05-07 21:09:13,772 file_cache is unavailable when using oauth2client >= 4.0.0
Traceback (most recent call last):
  File "/usr/local/lib/python3.6/site-packages/google_api_python_client-1.6.2-py3.6.egg/googleapiclient/discovery_cache/__init__.py", line 36, in autodetect
    from google.appengine.api import memcache
ModuleNotFoundError: No module named 'google'

During handling of the above exception, another exception occurred:

Traceback (most recent call last):
  File "/usr/local/lib/python3.6/site-packages/google_api_python_client-1.6.2-py3.6.egg/googleapiclient/discovery_cache/file_cache.py", line 33, in <module>
    from oauth2client.contrib.locked_file import LockedFile
ModuleNotFoundError: No module named 'oauth2client.contrib.locked_file'

During handling of the above exception, another exception occurred:

Traceback (most recent call last):
  File "/usr/local/lib/python3.6/site-packages/google_api_python_client-1.6.2-py3.6.egg/googleapiclient/discovery_cache/file_cache.py", line 37, in <module>
    from oauth2client.locked_file import LockedFile
ModuleNotFoundError: No module named 'oauth2client.locked_file'

During handling of the above exception, another exception occurred:

Traceback (most recent call last):
  File "/usr/local/lib/python3.6/site-packages/google_api_python_client-1.6.2-py3.6.egg/googleapiclient/discovery_cache/__init__.py", line 41, in autodetect
    from . import file_cache
  File "/usr/local/lib/python3.6/site-packages/google_api_python_client-1.6.2-py3.6.egg/googleapiclient/discovery_cache/file_cache.py", line 41, in <module>
    'file_cache is unavailable when using oauth2client >= 4.0.0')
ImportError: file_cache is unavailable when using oauth2client >= 4.0.0
2017-05-07 21:09:13,774 URL being requested: GET https://www.googleapis.com/discovery/v1/apis/calendar/v3/rest
2017-05-07 21:09:13,974 URL being requested: GET https://www.googleapis.com/calendar/v3/calendars/primary/events?timeMin=2017-05-08T01%3A09%3A13.937586Z&maxResults=10&singleEvents=true&orderBy=startTime&alt=json
2017-05-07 21:09:14,017 Refreshing due to a 401 (attempt 1/2)
2017-05-07 21:09:14,019 Refreshing access_token
2017-05-07 21:09:14,323 0.152.255.115.20's event has been collected
2017-05-07 21:09:25,222 Notify 0.152.255.115.20 event in 5 min
2017-05-07 21:11:45,152 149.54.23.70.242 tries to log in but has not registered yet
2017-05-07 21:12:04,808 211.127.98.139.69 tries to log in but has not registered yet
2017-05-07 21:12:27,066 211.127.98.139.69 tries to log in but has not registered yet
2017-05-07 21:14:11,177 0.152.255.115.20 has logged in
2017-05-07 21:14:11,198 file_cache is unavailable when using oauth2client >= 4.0.0
Traceback (most recent call last):
  File "/usr/local/lib/python3.6/site-packages/google_api_python_client-1.6.2-py3.6.egg/googleapiclient/discovery_cache/__init__.py", line 36, in autodetect
    from google.appengine.api import memcache
ModuleNotFoundError: No module named 'google'

During handling of the above exception, another exception occurred:

Traceback (most recent call last):
  File "/usr/local/lib/python3.6/site-packages/google_api_python_client-1.6.2-py3.6.egg/googleapiclient/discovery_cache/file_cache.py", line 33, in <module>
    from oauth2client.contrib.locked_file import LockedFile
ModuleNotFoundError: No module named 'oauth2client.contrib.locked_file'

During handling of the above exception, another exception occurred:

Traceback (most recent call last):
  File "/usr/local/lib/python3.6/site-packages/google_api_python_client-1.6.2-py3.6.egg/googleapiclient/discovery_cache/file_cache.py", line 37, in <module>
    from oauth2client.locked_file import LockedFile
ModuleNotFoundError: No module named 'oauth2client.locked_file'

During handling of the above exception, another exception occurred:

Traceback (most recent call last):
  File "/usr/local/lib/python3.6/site-packages/google_api_python_client-1.6.2-py3.6.egg/googleapiclient/discovery_cache/__init__.py", line 41, in autodetect
    from . import file_cache
  File "/usr/local/lib/python3.6/site-packages/google_api_python_client-1.6.2-py3.6.egg/googleapiclient/discovery_cache/file_cache.py", line 41, in <module>
    'file_cache is unavailable when using oauth2client >= 4.0.0')
ImportError: file_cache is unavailable when using oauth2client >= 4.0.0
2017-05-07 21:14:11,201 URL being requested: GET https://www.googleapis.com/discovery/v1/apis/calendar/v3/rest
2017-05-07 21:14:11,353 URL being requested: GET https://www.googleapis.com/calendar/v3/calendars/primary/events?timeMin=2017-05-08T01%3A14%3A11.323247Z&maxResults=10&singleEvents=true&orderBy=startTime&alt=json
2017-05-07 21:14:11,397 Refreshing due to a 401 (attempt 1/2)
2017-05-07 21:14:11,398 Refreshing access_token
2017-05-07 21:14:11,776 0.152.255.115.20's event has been collected
2017-05-07 21:14:11,807 Notify 0.152.255.115.20 event in 6 min
2017-05-07 21:14:12,789 211.127.98.139.69 tries to log in but has not registered yet
2017-05-07 21:14:58,263 211.127.98.139.69 tries to log in but has not registered yet
2017-05-07 21:15:29,901 211.127.98.139.69 tries to log in but has not registered yet
2017-05-07 21:15:38,619 211.127.98.139.69 tries to log in but has not registered yet
2017-05-07 21:15:55,690 211.127.98.139.69 tries to log in but has not registered yet
2017-05-07 21:15:56,847 211.127.98.139.69 tries to log in but has not registered yet
2017-05-07 21:15:58,045 211.127.98.139.69 tries to log in but has not registered yet
2017-05-07 21:15:59,152 211.127.98.139.69 tries to log in but has not registered yet
2017-05-07 21:16:00,304 211.127.98.139.69 tries to log in but has not registered yet
2017-05-07 21:16:01,425 211.127.98.139.69 tries to log in but has not registered yet
2017-05-07 21:16:02,598 211.127.98.139.69 tries to log in but has not registered yet
2017-05-07 21:16:02,835 Retransmission, Message ID: 61826.
2017-05-07 21:16:03,873 211.127.98.139.69 tries to log in but has not registered yet
2017-05-07 21:16:04,898 211.127.98.139.69 tries to log in but has not registered yet
2017-05-07 21:16:06,165 211.127.98.139.69 tries to log in but has not registered yet
2017-05-07 21:16:07,349 211.127.98.139.69 tries to log in but has not registered yet
2017-05-07 21:16:08,547 211.127.98.139.69 tries to log in but has not registered yet
2017-05-07 21:16:09,706 211.127.98.139.69 tries to log in but has not registered yet
2017-05-07 21:16:10,935 211.127.98.139.69 tries to log in but has not registered yet
2017-05-07 21:16:14,849 211.127.98.139.69 tries to log in but has not registered yet
2017-05-07 21:16:17,825 211.127.98.139.69 tries to log in but has not registered yet
2017-05-07 21:16:18,957 211.127.98.139.69 tries to log in but has not registered yet
2017-05-07 21:16:20,147 211.127.98.139.69 tries to log in but has not registered yet
2017-05-07 21:16:21,333 211.127.98.139.69 tries to log in but has not registered yet
2017-05-07 21:16:22,577 211.127.98.139.69 tries to log in but has not registered yet
2017-05-07 21:16:23,698 211.127.98.139.69 tries to log in but has not registered yet
2017-05-07 21:16:24,853 211.127.98.139.69 tries to log in but has not registered yet
2017-05-07 21:16:26,040 211.127.98.139.69 tries to log in but has not registered yet
2017-05-07 21:16:27,190 149.54.23.70.242 tries to log in but has not registered yet
2017-05-07 21:16:28,179 211.127.98.139.69 tries to log in but has not registered yet
2017-05-07 21:16:29,216 149.54.23.70.242 tries to log in but has not registered yet
2017-05-07 21:16:29,419 file_cache is unavailable when using oauth2client >= 4.0.0
Traceback (most recent call last):
  File "/usr/local/lib/python3.6/site-packages/google_api_python_client-1.6.2-py3.6.egg/googleapiclient/discovery_cache/__init__.py", line 36, in autodetect
    from google.appengine.api import memcache
ModuleNotFoundError: No module named 'google'

During handling of the above exception, another exception occurred:

Traceback (most recent call last):
  File "/usr/local/lib/python3.6/site-packages/google_api_python_client-1.6.2-py3.6.egg/googleapiclient/discovery_cache/file_cache.py", line 33, in <module>
    from oauth2client.contrib.locked_file import LockedFile
ModuleNotFoundError: No module named 'oauth2client.contrib.locked_file'

During handling of the above exception, another exception occurred:

Traceback (most recent call last):
  File "/usr/local/lib/python3.6/site-packages/google_api_python_client-1.6.2-py3.6.egg/googleapiclient/discovery_cache/file_cache.py", line 37, in <module>
    from oauth2client.locked_file import LockedFile
ModuleNotFoundError: No module named 'oauth2client.locked_file'

During handling of the above exception, another exception occurred:

Traceback (most recent call last):
  File "/usr/local/lib/python3.6/site-packages/google_api_python_client-1.6.2-py3.6.egg/googleapiclient/discovery_cache/__init__.py", line 41, in autodetect
    from . import file_cache
  File "/usr/local/lib/python3.6/site-packages/google_api_python_client-1.6.2-py3.6.egg/googleapiclient/discovery_cache/file_cache.py", line 41, in <module>
    'file_cache is unavailable when using oauth2client >= 4.0.0')
ImportError: file_cache is unavailable when using oauth2client >= 4.0.0
2017-05-07 21:16:29,431 URL being requested: GET https://www.googleapis.com/discovery/v1/apis/calendar/v3/rest
2017-05-07 21:16:29,865 URL being requested: GET https://www.googleapis.com/calendar/v3/calendars/primary/events?timeMin=2017-05-08T01%3A16%3A29.802755Z&maxResults=10&singleEvents=true&orderBy=startTime&alt=json
2017-05-07 21:16:29,986 Updating 0.152.255.115.20's event list
2017-05-07 21:16:29,991 0.152.255.115.20's event has been collected
2017-05-07 21:17:59,811 211.127.98.139.69 tries to log in but has not registered yet
2017-05-07 21:18:01,638 0.152.255.115.20 has logged in
2017-05-07 21:18:01,657 file_cache is unavailable when using oauth2client >= 4.0.0
Traceback (most recent call last):
  File "/usr/local/lib/python3.6/site-packages/google_api_python_client-1.6.2-py3.6.egg/googleapiclient/discovery_cache/__init__.py", line 36, in autodetect
    from google.appengine.api import memcache
ModuleNotFoundError: No module named 'google'

During handling of the above exception, another exception occurred:

Traceback (most recent call last):
  File "/usr/local/lib/python3.6/site-packages/google_api_python_client-1.6.2-py3.6.egg/googleapiclient/discovery_cache/file_cache.py", line 33, in <module>
    from oauth2client.contrib.locked_file import LockedFile
ModuleNotFoundError: No module named 'oauth2client.contrib.locked_file'

During handling of the above exception, another exception occurred:

Traceback (most recent call last):
  File "/usr/local/lib/python3.6/site-packages/google_api_python_client-1.6.2-py3.6.egg/googleapiclient/discovery_cache/file_cache.py", line 37, in <module>
    from oauth2client.locked_file import LockedFile
ModuleNotFoundError: No module named 'oauth2client.locked_file'

During handling of the above exception, another exception occurred:

Traceback (most recent call last):
  File "/usr/local/lib/python3.6/site-packages/google_api_python_client-1.6.2-py3.6.egg/googleapiclient/discovery_cache/__init__.py", line 41, in autodetect
    from . import file_cache
  File "/usr/local/lib/python3.6/site-packages/google_api_python_client-1.6.2-py3.6.egg/googleapiclient/discovery_cache/file_cache.py", line 41, in <module>
    'file_cache is unavailable when using oauth2client >= 4.0.0')
ImportError: file_cache is unavailable when using oauth2client >= 4.0.0
2017-05-07 21:18:01,660 URL being requested: GET https://www.googleapis.com/discovery/v1/apis/calendar/v3/rest
2017-05-07 21:18:01,819 URL being requested: GET https://www.googleapis.com/calendar/v3/calendars/primary/events?timeMin=2017-05-08T01%3A18%3A01.789698Z&maxResults=10&singleEvents=true&orderBy=startTime&alt=json
2017-05-07 21:18:01,861 Refreshing due to a 401 (attempt 1/2)
2017-05-07 21:18:01,863 Refreshing access_token
2017-05-07 21:18:02,131 0.152.255.115.20's event has been collected
2017-05-07 21:18:08,389 149.54.23.70.242 tries to log in but has not registered yet
2017-05-07 21:18:13,579 Notify 0.152.255.115.20 event in 5 min
2017-05-07 21:20:38,984 211.127.98.139.69 tries to log in but has not registered yet
2017-05-07 21:21:12,365 211.127.98.139.69 tries to log in but has not registered yet
2017-05-07 21:21:22,146 149.54.23.70.242 tries to log in but has not registered yet
2017-05-07 21:21:23,476 0.152.255.115.20 has logged in
2017-05-07 21:21:23,495 file_cache is unavailable when using oauth2client >= 4.0.0
Traceback (most recent call last):
  File "/usr/local/lib/python3.6/site-packages/google_api_python_client-1.6.2-py3.6.egg/googleapiclient/discovery_cache/__init__.py", line 36, in autodetect
    from google.appengine.api import memcache
ModuleNotFoundError: No module named 'google'

During handling of the above exception, another exception occurred:

Traceback (most recent call last):
  File "/usr/local/lib/python3.6/site-packages/google_api_python_client-1.6.2-py3.6.egg/googleapiclient/discovery_cache/file_cache.py", line 33, in <module>
    from oauth2client.contrib.locked_file import LockedFile
ModuleNotFoundError: No module named 'oauth2client.contrib.locked_file'

During handling of the above exception, another exception occurred:

Traceback (most recent call last):
  File "/usr/local/lib/python3.6/site-packages/google_api_python_client-1.6.2-py3.6.egg/googleapiclient/discovery_cache/file_cache.py", line 37, in <module>
    from oauth2client.locked_file import LockedFile
ModuleNotFoundError: No module named 'oauth2client.locked_file'

During handling of the above exception, another exception occurred:

Traceback (most recent call last):
  File "/usr/local/lib/python3.6/site-packages/google_api_python_client-1.6.2-py3.6.egg/googleapiclient/discovery_cache/__init__.py", line 41, in autodetect
    from . import file_cache
  File "/usr/local/lib/python3.6/site-packages/google_api_python_client-1.6.2-py3.6.egg/googleapiclient/discovery_cache/file_cache.py", line 41, in <module>
    'file_cache is unavailable when using oauth2client >= 4.0.0')
ImportError: file_cache is unavailable when using oauth2client >= 4.0.0
2017-05-07 21:21:23,498 URL being requested: GET https://www.googleapis.com/discovery/v1/apis/calendar/v3/rest
2017-05-07 21:21:23,671 URL being requested: GET https://www.googleapis.com/calendar/v3/calendars/primary/events?timeMin=2017-05-08T01%3A21%3A23.642607Z&maxResults=10&singleEvents=true&orderBy=startTime&alt=json
2017-05-07 21:21:23,729 Refreshing due to a 401 (attempt 1/2)
2017-05-07 21:21:23,730 Refreshing access_token
2017-05-07 21:21:24,024 0.152.255.115.20's event has been collected
2017-05-07 21:22:16,709 0.152.255.115.20 has logged in
2017-05-07 21:22:16,728 file_cache is unavailable when using oauth2client >= 4.0.0
Traceback (most recent call last):
  File "/usr/local/lib/python3.6/site-packages/google_api_python_client-1.6.2-py3.6.egg/googleapiclient/discovery_cache/__init__.py", line 36, in autodetect
    from google.appengine.api import memcache
ModuleNotFoundError: No module named 'google'

During handling of the above exception, another exception occurred:

Traceback (most recent call last):
  File "/usr/local/lib/python3.6/site-packages/google_api_python_client-1.6.2-py3.6.egg/googleapiclient/discovery_cache/file_cache.py", line 33, in <module>
    from oauth2client.contrib.locked_file import LockedFile
ModuleNotFoundError: No module named 'oauth2client.contrib.locked_file'

During handling of the above exception, another exception occurred:

Traceback (most recent call last):
  File "/usr/local/lib/python3.6/site-packages/google_api_python_client-1.6.2-py3.6.egg/googleapiclient/discovery_cache/file_cache.py", line 37, in <module>
    from oauth2client.locked_file import LockedFile
ModuleNotFoundError: No module named 'oauth2client.locked_file'

During handling of the above exception, another exception occurred:

Traceback (most recent call last):
  File "/usr/local/lib/python3.6/site-packages/google_api_python_client-1.6.2-py3.6.egg/googleapiclient/discovery_cache/__init__.py", line 41, in autodetect
    from . import file_cache
  File "/usr/local/lib/python3.6/site-packages/google_api_python_client-1.6.2-py3.6.egg/googleapiclient/discovery_cache/file_cache.py", line 41, in <module>
    'file_cache is unavailable when using oauth2client >= 4.0.0')
ImportError: file_cache is unavailable when using oauth2client >= 4.0.0
2017-05-07 21:22:16,731 URL being requested: GET https://www.googleapis.com/discovery/v1/apis/calendar/v3/rest
2017-05-07 21:22:16,908 URL being requested: GET https://www.googleapis.com/calendar/v3/calendars/primary/events?timeMin=2017-05-08T01%3A22%3A16.879018Z&maxResults=10&singleEvents=true&orderBy=startTime&alt=json
2017-05-07 21:22:16,951 Refreshing due to a 401 (attempt 1/2)
2017-05-07 21:22:16,952 Refreshing access_token
2017-05-07 21:22:17,219 0.152.255.115.20's event has been collected
2017-05-07 21:22:28,403 Notify 0.152.255.115.20 event in 5 min
2017-05-07 21:24:34,579 file_cache is unavailable when using oauth2client >= 4.0.0
Traceback (most recent call last):
  File "/usr/local/lib/python3.6/site-packages/google_api_python_client-1.6.2-py3.6.egg/googleapiclient/discovery_cache/__init__.py", line 36, in autodetect
    from google.appengine.api import memcache
ModuleNotFoundError: No module named 'google'

During handling of the above exception, another exception occurred:

Traceback (most recent call last):
  File "/usr/local/lib/python3.6/site-packages/google_api_python_client-1.6.2-py3.6.egg/googleapiclient/discovery_cache/file_cache.py", line 33, in <module>
    from oauth2client.contrib.locked_file import LockedFile
ModuleNotFoundError: No module named 'oauth2client.contrib.locked_file'

During handling of the above exception, another exception occurred:

Traceback (most recent call last):
  File "/usr/local/lib/python3.6/site-packages/google_api_python_client-1.6.2-py3.6.egg/googleapiclient/discovery_cache/file_cache.py", line 37, in <module>
    from oauth2client.locked_file import LockedFile
ModuleNotFoundError: No module named 'oauth2client.locked_file'

During handling of the above exception, another exception occurred:

Traceback (most recent call last):
  File "/usr/local/lib/python3.6/site-packages/google_api_python_client-1.6.2-py3.6.egg/googleapiclient/discovery_cache/__init__.py", line 41, in autodetect
    from . import file_cache
  File "/usr/local/lib/python3.6/site-packages/google_api_python_client-1.6.2-py3.6.egg/googleapiclient/discovery_cache/file_cache.py", line 41, in <module>
    'file_cache is unavailable when using oauth2client >= 4.0.0')
ImportError: file_cache is unavailable when using oauth2client >= 4.0.0
2017-05-07 21:24:34,593 URL being requested: GET https://www.googleapis.com/discovery/v1/apis/calendar/v3/rest
2017-05-07 21:24:35,019 URL being requested: GET https://www.googleapis.com/calendar/v3/calendars/primary/events?timeMin=2017-05-08T01%3A24%3A34.955991Z&maxResults=10&singleEvents=true&orderBy=startTime&alt=json
2017-05-07 21:24:35,131 Updating 0.152.255.115.20's event list
